Workbook

Sheet README
A1: 2D Heat Diffusion on the GPU: data behind the graphs
A3: Sheet | B3: Contents and source
A4: T4_benchmark | B4: Tesla T4 (Google Colab) benchmark, copied from results/benchmark_t4.csv in the GitHub repository. 500 GPU / 20 CPU sweeps per run, fastest of 3.
A5: Shared_vs_global | B5: Ratio of global to shared time per sweep (formulas on T4_benchmark). Above 1 = shared is faster.
A6: T4_tuning | B6: Tuning at N = 1024, copied from results/tuning_t4.csv: block shape x cells per thread x float precision x check interval.
A7: Sweeps_vs_N | B7: Sweeps to reach eps = 1e-4 for N = 9 ... 257 and each boundary case, from heat/cpu_reference.py. Centre error is a formula.
A8: Transfers | B8: Bytes copied GPU -> CPU per run: this project (grid once + 16 bytes per check) vs copying the grid every sweep. Formulas on Sweeps_vs_N (case 3c).
A9: Sweeps_vs_eps | B9: Sweeps and centre error against eps (case 3c, N = 17, 33, 65), from heat/cpu_reference.py.
A10: Convergence_history | B10: Largest change in every sweep, case 3c, N = 17, 33, 65, 129, run to eps = 1e-6 (same update and stop rule as heat/cpu_reference.py).
A11: Centre_trajectory | B11: Centre temperature after every sweep, N = 65, each case, run to eps = 1e-6.
A12: Plate_3a / 3b / 3c | B12: Converged 65 x 65 plates (eps = 1e-8), rounded to 4 decimals.
A13: Middle_row | B13: Middle row (row 32) of each plate, as formulas on the Plate sheets.
A15: Colours | B15: Blue text = values copied from a run or a CSV file. Black text = formulas.
A16: Boundary cases | B16: 3a uniform: every boundary cell 75. 3b edges: top 100, bottom 40, left 20, right 0. 3c hot edge: top 100, other edges 0.

Sheet T4_benchmark
A1: n | B1: backend | C1: block | D1: coarsen | E1: dtype | F1: check_every | G1: sweeps | H1: ms_per_sweep | I1: effective_gb_s | J1: speedup_vs_cpu
A2: 256 | B2: cpu_reference | F2: 1 | G2: 20 | H2: 0.5251 | I2: 2 | J2: 1
A3: 256 | B3: cuda_global | C3: 16x16 | D3: 1 | E3: float64 | F3: 1 | G3: 500 | H3: 0.0898 | I3: 11.68 | J3: 5.9
A4: 256 | B4: cuda_global | C4: 16x16 | D4: 1 | E4: float64 | F4: 50 | G4: 500 | H4: 0.0425 | I4: 24.69 | J4: 12.4
A5: 256 | B5: cuda_shared | C5: 16x16 | D5: 1 | E5: float64 | F5: 1 | G5: 500 | H5: 0.0877 | I5: 11.96 | J5: 6
A6: 256 | B6: cuda_shared | C6: 16x16 | D6: 1 | E6: float64 | F6: 50 | G6: 500 | H6: 0.0427 | I6: 24.53 | J6: 12.3
A7: 512 | B7: cpu_reference | F7: 1 | G7: 20 | H7: 4.3679 | I7: 0.96 | J7: 1
A8: 512 | B8: cuda_global | C8: 16x16 | D8: 1 | E8: float64 | F8: 1 | G8: 500 | H8: 0.1335 | I8: 31.41 | J8: 32.7
A9: 512 | B9: cuda_global | C9: 16x16 | D9: 1 | E9: float64 | F9: 50 | G9: 500 | H9: 0.0454 | I9: 92.37 | J9: 96.2
A10: 512 | B10: cuda_shared | C10: 16x16 | D10: 1 | E10: float64 | F10: 1 | G10: 500 | H10: 0.1212 | I10: 34.62 | J10: 36.1
A11: 512 | B11: cuda_shared | C11: 16x16 | D11: 1 | E11: float64 | F11: 50 | G11: 500 | H11: 0.0467 | I11: 89.84 | J11: 93.6
A12: 1024 | B12: cpu_reference | F12: 1 | G12: 20 | H12: 12.9594 | I12: 1.29 | J12: 1
A13: 1024 | B13: cuda_global | C13: 16x16 | D13: 1 | E13: float64 | F13: 1 | G13: 500 | H13: 0.1723 | I13: 97.34 | J13: 75.2
A14: 1024 | B14: cuda_global | C14: 16x16 | D14: 1 | E14: float64 | F14: 50 | G14: 500 | H14: 0.0773 | I14: 217.14 | J14: 167.7
A15: 1024 | B15: cuda_shared | C15: 16x16 | D15: 1 | E15: float64 | F15: 1 | G15: 500 | H15: 0.2116 | I15: 79.27 | J15: 61.2
A16: 1024 | B16: cuda_shared | C16: 16x16 | D16: 1 | E16: float64 | F16: 50 | G16: 500 | H16: 0.0883 | I16: 190.1 | J16: 146.8
A17: 2048 | B17: cpu_reference | F17: 1 | G17: 20 | H17: 69.9144 | I17: 0.96 | J17: 1
A18: 2048 | B18: cuda_global | C18: 16x16 | D18: 1 | E18: float64 | F18: 1 | G18: 500 | H18: 0.5032 | I18: 133.38 | J18: 139
A19: 2048 | B19: cuda_global | C19: 16x16 | D19: 1 | E19: float64 | F19: 50 | G19: 500 | H19: 0.2922 | I19: 229.68 | J19: 239.3
A20: 2048 | B20: cuda_shared | C20: 16x16 | D20: 1 | E20: float64 | F20: 1 | G20: 500 | H20: 0.6177 | I20: 108.65 | J20: 113.2
A21: 2048 | B21: cuda_shared | C21: 16x16 | D21: 1 | E21: float64 | F21: 50 | G21: 500 | H21: 0.3476 | I21: 193.06 | J21: 201.1

Sheet Shared_vs_global
A1: n | B1: check_every | C1: global ms/sweep | D1: shared ms/sweep | E1: global / shared
A2: 256 | B2: 1 | C2: =SUMIFS(T4_benchmark!$H$2:$H$21,T4_benchmark!$A$2:$A$21,$A2,T4_benchmark!$F$2:$F$21,$B2,T4_benchmark!$B$2:$B$21,"cuda_global") -> 0.0898 | D2: =SUMIFS(T4_benchmark!$H$2:$H$21,T4_benchmark!$A$2:$A$21,$A2,T4_benchmark!$F$2:$F$21,$B2,T4_benchmark!$B$2:$B$21,"cuda_shared") -> 0.0877 | E2: =IF(D2=0,"",C2/D2) -> 1.0239453
A3: 256 | B3: 50 | C3: =SUMIFS(T4_benchmark!$H$2:$H$21,T4_benchmark!$A$2:$A$21,$A3,T4_benchmark!$F$2:$F$21,$B3,T4_benchmark!$B$2:$B$21,"cuda_global") -> 0.0425 | D3: =SUMIFS(T4_benchmark!$H$2:$H$21,T4_benchmark!$A$2:$A$21,$A3,T4_benchmark!$F$2:$F$21,$B3,T4_benchmark!$B$2:$B$21,"cuda_shared") -> 0.0427 | E3: =IF(D3=0,"",C3/D3) -> 0.99531616
A4: 512 | B4: 1 | C4: =SUMIFS(T4_benchmark!$H$2:$H$21,T4_benchmark!$A$2:$A$21,$A4,T4_benchmark!$F$2:$F$21,$B4,T4_benchmark!$B$2:$B$21,"cuda_global") -> 0.1335 | D4: =SUMIFS(T4_benchmark!$H$2:$H$21,T4_benchmark!$A$2:$A$21,$A4,T4_benchmark!$F$2:$F$21,$B4,T4_benchmark!$B$2:$B$21,"cuda_shared") -> 0.1212 | E4: =IF(D4=0,"",C4/D4) -> 1.1014851
A5: 512 | B5: 50 | C5: =SUMIFS(T4_benchmark!$H$2:$H$21,T4_benchmark!$A$2:$A$21,$A5,T4_benchmark!$F$2:$F$21,$B5,T4_benchmark!$B$2:$B$21,"cuda_global") -> 0.0454 | D5: =SUMIFS(T4_benchmark!$H$2:$H$21,T4_benchmark!$A$2:$A$21,$A5,T4_benchmark!$F$2:$F$21,$B5,T4_benchmark!$B$2:$B$21,"cuda_shared") -> 0.0467 | E5: =IF(D5=0,"",C5/D5) -> 0.97216274
A6: 1024 | B6: 1 | C6: =SUMIFS(T4_benchmark!$H$2:$H$21,T4_benchmark!$A$2:$A$21,$A6,T4_benchmark!$F$2:$F$21,$B6,T4_benchmark!$B$2:$B$21,"cuda_global") -> 0.1723 | D6: =SUMIFS(T4_benchmark!$H$2:$H$21,T4_benchmark!$A$2:$A$21,$A6,T4_benchmark!$F$2:$F$21,$B6,T4_benchmark!$B$2:$B$21,"cuda_shared") -> 0.2116 | E6: =IF(D6=0,"",C6/D6) -> 0.81427221
A7: 1024 | B7: 50 | C7: =SUMIFS(T4_benchmark!$H$2:$H$21,T4_benchmark!$A$2:$A$21,$A7,T4_benchmark!$F$2:$F$21,$B7,T4_benchmark!$B$2:$B$21,"cuda_global") -> 0.0773 | D7: =SUMIFS(T4_benchmark!$H$2:$H$21,T4_benchmark!$A$2:$A$21,$A7,T4_benchmark!$F$2:$F$21,$B7,T4_benchmark!$B$2:$B$21,"cuda_shared") -> 0.0883 | E7: =IF(D7=0,"",C7/D7) -> 0.87542469
A8: 2048 | B8: 1 | C8: =SUMIFS(T4_benchmark!$H$2:$H$21,T4_benchmark!$A$2:$A$21,$A8,T4_benchmark!$F$2:$F$21,$B8,T4_benchmark!$B$2:$B$21,"cuda_global") -> 0.5032 | D8: =SUMIFS(T4_benchmark!$H$2:$H$21,T4_benchmark!$A$2:$A$21,$A8,T4_benchmark!$F$2:$F$21,$B8,T4_benchmark!$B$2:$B$21,"cuda_shared") -> 0.6177 | E8: =IF(D8=0,"",C8/D8) -> 0.81463494
A9: 2048 | B9: 50 | C9: =SUMIFS(T4_benchmark!$H$2:$H$21,T4_benchmark!$A$2:$A$21,$A9,T4_benchmark!$F$2:$F$21,$B9,T4_benchmark!$B$2:$B$21,"cuda_global") -> 0.2922 | D9: =SUMIFS(T4_benchmark!$H$2:$H$21,T4_benchmark!$A$2:$A$21,$A9,T4_benchmark!$F$2:$F$21,$B9,T4_benchmark!$B$2:$B$21,"cuda_shared") -> 0.3476 | E9: =IF(D9=0,"",C9/D9) -> 0.8406214

Sheet T4_tuning
A1: n | B1: backend | C1: block | D1: coarsen | E1: dtype | F1: check_every | G1: sweeps | H1: ms_per_sweep | I1: effective_gb_s | J1: speedup_vs_cpu
A2: 1024 | B2: cpu_reference | F2: 1 | G2: 20 | H2: 13.039 | I2: 1.29 | J2: 1
A3: 1024 | B3: cuda_global | C3: 16x16 | D3: 1 | E3: float64 | F3: 1 | G3: 500 | H3: 0.2 | I3: 83.89 | J3: 65.2
A4: 1024 | B4: cuda_global | C4: 16x16 | D4: 1 | E4: float64 | F4: 50 | G4: 500 | H4: 0.0774 | I4: 216.79 | J4: 168.5
A5: 1024 | B5: cuda_global | C5: 16x16 | D5: 1 | E5: float32 | F5: 1 | G5: 500 | H5: 0.1303 | I5: 64.36 | J5: 100
A6: 1024 | B6: cuda_global | C6: 16x16 | D6: 1 | E6: float32 | F6: 50 | G6: 500 | H6: 0.0415 | I6: 201.94 | J6: 313.9
A7: 1024 | B7: cuda_global | C7: 16x16 | D7: 2 | E7: float64 | F7: 1 | G7: 500 | H7: 0.1592 | I7: 105.39 | J7: 81.9
A8: 1024 | B8: cuda_global | C8: 16x16 | D8: 2 | E8: float64 | F8: 50 | G8: 500 | H8: 0.0786 | I8: 213.46 | J8: 165.9
A9: 1024 | B9: cuda_global | C9: 16x16 | D9: 2 | E9: float32 | F9: 1 | G9: 500 | H9: 0.107 | I9: 78.38 | J9: 121.8
A10: 1024 | B10: cuda_global | C10: 16x16 | D10: 2 | E10: float32 | F10: 50 | G10: 500 | H10: 0.0472 | I10: 177.75 | J10: 276.3
A11: 1024 | B11: cuda_global | C11: 16x16 | D11: 4 | E11: float64 | F11: 1 | G11: 500 | H11: 0.156 | I11: 107.56 | J11: 83.6
A12: 1024 | B12: cuda_global | C12: 16x16 | D12: 4 | E12: float64 | F12: 50 | G12: 500 | H12: 0.0818 | I12: 205.2 | J12: 159.5
A13: 1024 | B13: cuda_global | C13: 16x16 | D13: 4 | E13: float32 | F13: 1 | G13: 500 | H13: 0.1093 | I13: 76.77 | J13: 119.3
A14: 1024 | B14: cuda_global | C14: 16x16 | D14: 4 | E14: float32 | F14: 50 | G14: 500 | H14: 0.0431 | I14: 194.68 | J14: 302.6
... A74: 1024 | B74: cuda_shared | C74: 32x16 | D74: 4 | E74: float32 | F74: 50 | G74: 500 | H74: 0.0501 | I74: 167.45 | J74: 260.3

Sheet Sweeps_vs_N
A1: case | B1: n | C1: eps | D1: sweeps | E1: centre temperature | F1: exact centre | G1: centre error | H1: CPU seconds
A2: 3a uniform | B2: 9 | C2: 0.0001 | D2: 146 | E2: 74.998867 | F2: 75 | G2: =ABS(E2-F2) -> 0.001133 | H2: 0.0013
A3: 3a uniform | B3: 17 | C3: 0.0001 | D3: 520 | E3: 74.994981 | F3: 75 | G3: =ABS(E3-F3) -> 0.005019 | H3: 0.0051
A4: 3a uniform | B4: 33 | C4: 0.0001 | D4: 1798 | E4: 74.979344 | F4: 75 | G4: =ABS(E4-F4) -> 0.020656 | H4: 0.0235
A5: 3a uniform | B5: 65 | C5: 0.0001 | D5: 6050 | E5: 74.917228 | F5: 75 | G5: =ABS(E5-F5) -> 0.082772 | H5: 0.1959
A6: 3a uniform | B6: 129 | C6: 0.0001 | D6: 19598 | E6: 74.668101 | F6: 75 | G6: =ABS(E6-F6) -> 0.331899 | H6: 1.6269
A7: 3a uniform | B7: 257 | C7: 0.0001 | D7: 59986 | E7: 73.672116 | F7: 75 | G7: =ABS(E7-F7) -> 1.327884 | H7: 54.3007
A8: 3b edges | B8: 9 | C8: 0.0001 | D8: 138 | E8: 39.998862 | F8: 40 | G8: =ABS(E8-F8) -> 0.001138 | H8: 0.0012
A9: 3b edges | B9: 17 | C9: 0.0001 | D9: 488 | E9: 39.99502 | F9: 40 | G9: =ABS(E9-F9) -> 0.00498 | H9: 0.0061
A10: 3b edges | B10: 33 | C10: 0.0001 | D10: 1668 | E10: 39.979367 | F10: 40 | G10: =ABS(E10-F10) -> 0.020633 | H10: 0.0212
A11: 3b edges | B11: 65 | C11: 0.0001 | D11: 5528 | E11: 39.917183 | F11: 40 | G11: =ABS(E11-F11) -> 0.082817 | H11: 0.197
A12: 3b edges | B12: 129 | C12: 0.0001 | D12: 17512 | E12: 39.668184 | F12: 40 | G12: =ABS(E12-F12) -> 0.331816 | H12: 1.3707
A13: 3b edges | B13: 257 | C13: 0.0001 | D13: 51638 | E13: 38.672111 | F13: 40 | G13: =ABS(E13-F13) -> 1.327889 | H13: 45.7473
... A19: 3c hot edge | B19: 257 | C19: 0.0001 | D19: 45400 | E19: 23.672478 | F19: 25 | G19: =ABS(E19-F19) -> 1.327522 | H19: 41.3368

Sheet Transfers
A1: n | B1: sweeps (case 3c) | C1: bytes, this project | D1: bytes, grid every sweep | E1: ratio
A2: 9 | B2: =SUMIFS(Sweeps_vs_N!$D$2:$D$19,Sweeps_vs_N!$A$2:$A$19,"3c hot edge",Sweeps_vs_N!$B$2:$B$19,A2) -> 132 | C2: =8*A2^2+16*B2 -> 2760 | D2: =8*A2^2*B2 -> 85536 | E2: =D2/C2 -> 30.991304
A3: 17 | B3: =SUMIFS(Sweeps_vs_N!$D$2:$D$19,Sweeps_vs_N!$A$2:$A$19,"3c hot edge",Sweeps_vs_N!$B$2:$B$19,A3) -> 462 | C3: =8*A3^2+16*B3 -> 9704 | D3: =8*A3^2*B3 -> 1068144 | E3: =D3/C3 -> 110.07255
A4: 33 | B4: =SUMIFS(Sweeps_vs_N!$D$2:$D$19,Sweeps_vs_N!$A$2:$A$19,"3c hot edge",Sweeps_vs_N!$B$2:$B$19,A4) -> 1570 | C4: =8*A4^2+16*B4 -> 33832 | D4: =8*A4^2*B4 -> 13677840 | E4: =D4/C4 -> 404.28707
A5: 65 | B5: =SUMIFS(Sweeps_vs_N!$D$2:$D$19,Sweeps_vs_N!$A$2:$A$19,"3c hot edge",Sweeps_vs_N!$B$2:$B$19,A5) -> 5138 | C5: =8*A5^2+16*B5 -> 116008 | D5: =8*A5^2*B5 -> 173664400 | E5: =D5/C5 -> 1497.0037
A6: 129 | B6: =SUMIFS(Sweeps_vs_N!$D$2:$D$19,Sweeps_vs_N!$A$2:$A$19,"3c hot edge",Sweeps_vs_N!$B$2:$B$19,A6) -> 15952 | C6: =8*A6^2+16*B6 -> 388360 | D6: =8*A6^2*B6 -> 2123657856 | E6: =D6/C6 -> 5468.2713
A7: 257 | B7: =SUMIFS(Sweeps_vs_N!$D$2:$D$19,Sweeps_vs_N!$A$2:$A$19,"3c hot edge",Sweeps_vs_N!$B$2:$B$19,A7) -> 45400 | C7: =8*A7^2+16*B7 -> 1254792 | D7: =8*A7^2*B7 -> 23988996800 | E7: =D7/C7 -> 19117.907
A9: Bytes: 8 per float64 cell; 16 bytes per convergence check (two max slots).

Sheet Sweeps_vs_eps
A1: n | B1: eps | C1: sweeps | D1: centre error
A2: 17 | B2: 0.1 | C2: 107 | D2: 5.0498099
A3: 17 | B3: 0.01 | C3: 226 | D3: 0.50201251
A4: 17 | B4: 0.001 | C4: 344 | D4: 0.050867382
A5: 17 | B5: 0.0001 | C5: 462 | D5: 0.0051542351
A6: 17 | B6: 1e-05 | C6: 582 | D6: 0.00050238533
A7: 17 | B7: 1e-06 | C7: 700 | D7: 5.0905158e-05
A8: 17 | B8: 1e-07 | C8: 820 | D8: 4.9617458e-06
A9: 17 | B9: 1e-08 | C9: 938 | D9: 5.0275843e-07
A10: 33 | B10: 0.1 | C10: 192 | D10: 15.762027
A11: 33 | B11: 0.01 | C11: 617 | D11: 2.0589325
A12: 33 | B12: 0.001 | C12: 1094 | D12: 0.20592777
A13: 33 | B13: 0.0001 | C13: 1570 | D13: 0.020695559
... A25: 65 | B25: 1e-08 | C25: 12780 | D25: 8.2793584e-06

Sheet Convergence_history
A1: sweep | B1: N = 17 | C1: N = 33 | D1: N = 65 | E1: N = 129
A2: 1 | B2: 25 | C2: 25 | D2: 25 | E2: 25
A3: 2 | B3: 12.5 | C3: 12.5 | D3: 12.5 | E3: 12.5
A4: 3 | B4: 7.8125 | C4: 7.8125 | D4: 7.8125 | E4: 7.8125
A5: 4 | B5: 5.46875 | C5: 5.46875 | D5: 5.46875 | E5: 5.46875
A6: 5 | B6: 4.6875 | C6: 4.6875 | D6: 4.6875 | E6: 4.6875
A7: 6 | B7: 4.0283203 | C7: 4.0283203 | D7: 4.0283203 | E7: 4.0283203
A8: 7 | B8: 3.4912109 | C8: 3.4912109 | D8: 3.4912109 | E8: 3.4912109
A9: 8 | B9: 3.0548096 | C9: 3.0548096 | D9: 3.0548096 | E9: 3.0548096
A10: 9 | B10: 2.6977539 | C10: 2.6977539 | D10: 2.6977539 | E10: 2.6977539
A11: 10 | B11: 2.4009705 | C11: 2.4026871 | D11: 2.4026871 | E11: 2.4026871
A12: 11 | B12: 2.155304 | C12: 2.1562576 | D12: 2.1562576 | E12: 2.1562576
A13: 12 | B13: 1.9470215 | C13: 1.9483328 | D13: 1.9483328 | E13: 1.9483328
... A701: 700 | B701: 9.875238e-07 | C701: 0.0066738648 | D701: 0.028547463 | E701: 0.034520662
A702: 701 | C702: 0.0066576315 | D702: 0.028460574 | E702: 0.034470993
A703: 702 | C703: 0.0066095159 | D703: 0.028436163 | E703: 0.034422975
A704: 703 | C704: 0.0065936703 | D704: 0.028349622 | E704: 0.034373498
A705: 704 | C705: 0.0065457906 | D705: 0.028325375 | E705: 0.034325686
A706: 705 | C706: 0.0065303235 | D706: 0.02823918 | E706: 0.0342764
A707: 706 | C707: 0.0064826829 | D707: 0.028215097 | E707: 0.034228794
A708: 707 | C708: 0.0064675853 | D708: 0.028129248 | E708: 0.034179699
A709: 708 | C709: 0.0064201868 | D709: 0.028105327 | E709: 0.034132297
A710: 709 | C710: 0.0064054498 | D710: 0.028019822 | E710: 0.034083391
A711: 710 | C711: 0.0063582962 | D711: 0.027996063 | E711: 0.034036193
A712: 711 | C712: 0.0063439112 | D712: 0.0279109 | E712: 0.033987475
A713: 712 | C713: 0.0062970052 | D713: 0.027887301 | E713: 0.03394048
... A2525: 2524 | C2525: 9.9925044e-07 | D2525: 0.0023355047 | E2525: 0.0082128854
A2526: 2525 | D2526: 0.002330746 | E2526: 0.0082089955
A2527: 2526 | D2527: 0.0023298649 | E2527: 0.0082041322
A2528: 2527 | D2528: 0.0023251348 | E2528: 0.0082004298
A2529: 2528 | D2529: 0.0023242387 | E2529: 0.0081953902
A2530: 2529 | D2530: 0.0023195371 | E2530: 0.0081918748
A2531: 2530 | D2531: 0.0023186262 | E2531: 0.0081866595
A2532: 2531 | D2532: 0.0023139529 | E2532: 0.0081833303
A2533: 2532 | D2533: 0.0023130274 | E2533: 0.0081779401
A2534: 2533 | D2534: 0.0023083821 | E2534: 0.0081747964
A2535: 2534 | D2535: 0.0023074421 | E2535: 0.0081692319
A2536: 2535 | D2536: 0.0023028247 | E2536: 0.008166273
A2537: 2536 | D2537: 0.0023018703 | E2537: 0.0081605349
... A8959: 8958 | D8959: 9.9925482e-07 | E8959: 0.00082387873
...

Sheet Centre_trajectory
A1: sweep | B1: 3a uniform | C1: 3b edges | D1: 3c hot edge
A2: 1 | B2: 0 | C2: 0 | D2: 0
A3: 2 | B3: 0 | C3: 0 | D3: 0
A4: 3 | B4: 0 | C4: 0 | D4: 0
A5: 4 | B5: 0 | C5: 0 | D5: 0
A6: 5 | B6: 0 | C6: 0 | D6: 0
A7: 6 | B7: 0 | C7: 0 | D7: 0
A8: 7 | B8: 0 | C8: 0 | D8: 0
A9: 8 | B9: 0 | C9: 0 | D9: 0
A10: 9 | B10: 0 | C10: 0 | D10: 0
A11: 10 | B11: 0 | C11: 0 | D11: 0
A12: 11 | B12: 0 | C12: 0 | D12: 0
A13: 12 | B13: 0 | C13: 0 | D13: 0
... A8959: 8958 | B8959: 74.997513 | C8959: 39.998673 | D8959: 24.999171
A8960: 8959 | B8960: 74.997516 | C8960: 39.998675
A8961: 8960 | B8961: 74.997519 | C8961: 39.998677
A8962: 8961 | B8962: 74.997522 | C8962: 39.998678
A8963: 8962 | B8963: 74.997525 | C8963: 39.99868
A8964: 8963 | B8964: 74.997528 | C8964: 39.998681
A8965: 8964 | B8965: 74.997531 | C8965: 39.998683
A8966: 8965 | B8966: 74.997534 | C8966: 39.998685
A8967: 8966 | B8967: 74.997537 | C8967: 39.998686
A8968: 8967 | B8968: 74.99754 | C8968: 39.998688
A8969: 8968 | B8969: 74.997543 | C8969: 39.998689
A8970: 8969 | B8970: 74.997546 | C8970: 39.998691
A8971: 8970 | B8971: 74.997548 | C8971: 39.998693
... A9349: 9348 | B9349: 74.998446 | C9349: 39.999171
A9350: 9349 | B9350: 74.998447
A9351: 9350 | B9351: 74.998449
A9352: 9351 | B9352: 74.998451
A9353: 9352 | B9353: 74.998453
A9354: 9353 | B9354: 74.998455
A9355: 9354 | B9355: 74.998457
A9356: 9355 | B9356: 74.998459
A9357: 9356 | B9357: 74.99846
A9358: 9357 | B9358: 74.998462
A9359: 9358 | B9359: 74.998464
A9360: 9359 | B9360: 74.998466
A9361: 9360 | B9361: 74.998468
... A9871: 9870 | B9871: 74.999171

Sheet Plate_3a
A1: 75 | B1: 75 | C1: 75 | D1: 75 | E1: 75 | F1: 75 | G1: 75 | H1: 75 | I1: 75 | J1: 75 | K1: 75 | L1: 75 | M1: 75 | N1: 75 | O1: 75 | P1: 75 | Q1: 75 | R1: 75 | S1: 75 | T1: 75 | U1: 75 | V1: 75 | W1: 75 | X1: 75 | Y1: 75 | Z1: 75 | AA1: 75 | AB1: 75 | AC1: 75 | AD1: 75 | AE1: 75 | AF1: 75 | AG1: 75 | AH1: 75 | AI1: 75 | AJ1: 75 | AK1: 75 | AL1: 75 | AM1: 75 | AN1: 75 | AO1: 75 | AP1: 75 | AQ1: 75 | AR1: 75 | AS1: 75 | AT1: 75 | AU1: 75 | AV1: 75 | AW1: 75 | AX1: 75 | AY1: 75 | AZ1: 75 | BA1: 75 | BB1: 75 | BC1: 75 | BD1: 75 | BE1: 75 | BF1: 75 | BG1: 75 | BH1: 75 | BI1: 75 | BJ1: 75 | BK1: 75 | BL1: 75 | BM1: 75
A2: 75 | B2: 75 | C2: 75 | D2: 75 | E2: 75 | F2: 75 | G2: 75 | H2: 75 | I2: 75 | J2: 75 | K2: 75 | L2: 75 | M2: 75 | N2: 75 | O2: 75 | P2: 75 | Q2: 75 | R2: 75 | S2: 75 | T2: 75 | U2: 75 | V2: 75 | W2: 75 | X2: 75 | Y2: 75 | Z2: 75 | AA2: 75 | AB2: 75 | AC2: 75 | AD2: 75 | AE2: 75 | AF2: 75 | AG2: 75 | AH2: 75 | AI2: 75 | AJ2: 75 | AK2: 75 | AL2: 75 | AM2: 75 | AN2: 75 | AO2: 75 | AP2: 75 | AQ2: 75 | AR2: 75 | AS2: 75 | AT2: 75 | AU2: 75 | AV2: 75 | AW2: 75 | AX2: 75 | AY2: 75 | AZ2: 75 | BA2: 75 | BB2: 75 | BC2: 75 | BD2: 75 | BE2: 75 | BF2: 75 | BG2: 75 | BH2: 75 | BI2: 75 | BJ2: 75 | BK2: 75 | BL2: 75 | BM2: 75
A3: 75 | B3: 75 | C3: 75 | D3: 75 | E3: 75 | F3: 75 | G3: 75 | H3: 75 | I3: 75 | J3: 75 | K3: 75 | L3: 75 | M3: 75 | N3: 75 | O3: 75 | P3: 75 | Q3: 75 | R3: 75 | S3: 75 | T3: 75 | U3: 75 | V3: 75 | W3: 75 | X3: 75 | Y3: 75 | Z3: 75 | AA3: 75 | AB3: 75 | AC3: 75 | AD3: 75 | AE3: 75 | AF3: 75 | AG3: 75 | AH3: 75 | AI3: 75 | AJ3: 75 | AK3: 75 | AL3: 75 | AM3: 75 | AN3: 75 | AO3: 75 | AP3: 75 | AQ3: 75 | AR3: 75 | AS3: 75 | AT3: 75 | AU3: 75 | AV3: 75 | AW3: 75 | AX3: 75 | AY3: 75 | AZ3: 75 | BA3: 75 | BB3: 75 | BC3: 75 | BD3: 75 | BE3: 75 | BF3: 75 | BG3: 75 | BH3: 75 | BI3: 75 | BJ3: 75 | BK3: 75 | BL3: 75 | BM3: 75
A4: 75 | B4: 75 | C4: 75 | D4: 75 | E4: 75 | F4: 75 | G4: 75 | H4: 75 | I4: 75 | J4: 75 | K4: 75 | L4: 75 | M4: 75 | N4: 75 | O4: 75 | P4: 75 | Q4: 75 | R4: 75 | S4: 75 | T4: 75 | U4: 75 | V4: 75 | W4: 75 | X4: 75 | Y4: 75 | Z4: 75 | AA4: 75 | AB4: 75 | AC4: 75 | AD4: 75 | AE4: 75 | AF4: 75 | AG4: 75 | AH4: 75 | AI4: 75 | AJ4: 75 | AK4: 75 | AL4: 75 | AM4: 75 | AN4: 75 | AO4: 75 | AP4: 75 | AQ4: 75 | AR4: 75 | AS4: 75 | AT4: 75 | AU4: 75 | AV4: 75 | AW4: 75 | AX4: 75 | AY4: 75 | AZ4: 75 | BA4: 75 | BB4: 75 | BC4: 75 | BD4: 75 | BE4: 75 | BF4: 75 | BG4: 75 | BH4: 75 | BI4: 75 | BJ4: 75 | BK4: 75 | BL4: 75 | BM4: 75
A5: 75 | B5: 75 | C5: 75 | D5: 75 | E5: 75 | F5: 75 | G5: 75 | H5: 75 | I5: 75 | J5: 75 | K5: 75 | L5: 75 | M5: 75 | N5: 75 | O5: 75 | P5: 75 | Q5: 75 | R5: 75 | S5: 75 | T5: 75 | U5: 75 | V5: 75 | W5: 75 | X5: 75 | Y5: 75 | Z5: 75 | AA5: 75 | AB5: 75 | AC5: 75 | AD5: 75 | AE5: 75 | AF5: 75 | AG5: 75 | AH5: 75 | AI5: 75 | AJ5: 75 | AK5: 75 | AL5: 75 | AM5: 75 | AN5: 75 | AO5: 75 | AP5: 75 | AQ5: 75 | AR5: 75 | AS5: 75 | AT5: 75 | AU5: 75 | AV5: 75 | AW5: 75 | AX5: 75 | AY5: 75 | AZ5: 75 | BA5: 75 | BB5: 75 | BC5: 75 | BD5: 75 | BE5: 75 | BF5: 75 | BG5: 75 | BH5: 75 | BI5: 75 | BJ5: 75 | BK5: 75 | BL5: 75 | BM5: 75
A6: 75 | B6: 75 | C6: 75 | D6: 75 | E6: 75 | F6: 75 | G6: 75 | H6: 75 | I6: 75 | J6: 75 | K6: 75 | L6: 75 | M6: 75 | N6: 75 | O6: 75 | P6: 75 | Q6: 75 | R6: 75 | S6: 75 | T6: 75 | U6: 75 | V6: 75 | W6: 75 | X6: 75 | Y6: 75 | Z6: 75 | AA6: 75 | AB6: 75 | AC6: 75 | AD6: 75 | AE6: 75 | AF6: 75 | AG6: 75 | AH6: 75 | AI6: 75 | AJ6: 75 | AK6: 75 | AL6: 75 | AM6: 75 | AN6: 75 | AO6: 75 | AP6: 75 | AQ6: 75 | AR6: 75 | AS6: 75 | AT6: 75 | AU6: 75 | AV6: 75 | AW6: 75 | AX6: 75 | AY6: 75 | AZ6: 75 | BA6: 75 | BB6: 75 | BC6: 75 | BD6: 75 | BE6: 75 | BF6: 75 | BG6: 75 | BH6: 75 | BI6: 75 | BJ6: 75 | BK6: 75 | BL6: 75 | BM6: 75
A7: 75 | B7: 75 | C7: 75 | D7: 75 | E7: 75 | F7: 75 | G7: 75 | H7: 75 | I7: 75 | J7: 75 | K7: 75 | L7: 75 | M7: 75 | N7: 75 | O7: 75 | P7: 75 | Q7: 75 | R7: 75 | S7: 75 | T7: 75 | U7: 75 | V7: 75 | W7: 75 | X7: 75 | Y7: 75 | Z7: 75 | AA7: 75 | AB7: 75 | AC7: 75 | AD7: 75 | AE7: 75 | AF7: 75 | AG7: 75 | AH7: 75 | AI7: 75 | AJ7: 75 | AK7: 75 | AL7: 75 | AM7: 75 | AN7: 75 | AO7: 75 | AP7: 75 | AQ7: 75 | AR7: 75 | AS7: 75 | AT7: 75 | AU7: 75 | AV7: 75 | AW7: 75 | AX7: 75 | AY7: 75 | AZ7: 75 | BA7: 75 | BB7: 75 | BC7: 75 | BD7: 75 | BE7: 75 | BF7: 75 | BG7: 75 | BH7: 75 | BI7: 75 | BJ7: 75 | BK7: 75 | BL7: 75 | BM7: 75
A8: 75 | B8: 75 | C8: 75 | D8: 75 | E8: 75 | F8: 75 | G8: 75 | H8: 75 | I8: 75 | J8: 75 | K8: 75 | L8: 75 | M8: 75 | N8: 75 | O8: 75 | P8: 75 | Q8: 75 | R8: 75 | S8: 75 | T8: 75 | U8: 75 | V8: 75 | W8: 75 | X8: 75 | Y8: 75 | Z8: 75 | AA8: 75 | AB8: 75 | AC8: 75 | AD8: 75 | AE8: 75 | AF8: 75 | AG8: 75 | AH8: 75 | AI8: 75 | AJ8: 75 | AK8: 75 | AL8: 75 | AM8: 75 | AN8: 75 | AO8: 75 | AP8: 75 | AQ8: 75 | AR8: 75 | AS8: 75 | AT8: 75 | AU8: 75 | AV8: 75 | AW8: 75 | AX8: 75 | AY8: 75 | AZ8: 75 | BA8: 75 | BB8: 75 | BC8: 75 | BD8: 75 | BE8: 75 | BF8: 75 | BG8: 75 | BH8: 75 | BI8: 75 | BJ8: 75 | BK8: 75 | BL8: 75 | BM8: 75
A9: 75 | B9: 75 | C9: 75 | D9: 75 | E9: 75 | F9: 75 | G9: 75 | H9: 75 | I9: 75 | J9: 75 | K9: 75 | L9: 75 | M9: 75 | N9: 75 | O9: 75 | P9: 75 | Q9: 75 | R9: 75 | S9: 75 | T9: 75 | U9: 75 | V9: 75 | W9: 75 | X9: 75 | Y9: 75 | Z9: 75 | AA9: 75 | AB9: 75 | AC9: 75 | AD9: 75 | AE9: 75 | AF9: 75 | AG9: 75 | AH9: 75 | AI9: 75 | AJ9: 75 | AK9: 75 | AL9: 75 | AM9: 75 | AN9: 75 | AO9: 75 | AP9: 75 | AQ9: 75 | AR9: 75 | AS9: 75 | AT9: 75 | AU9: 75 | AV9: 75 | AW9: 75 | AX9: 75 | AY9: 75 | AZ9: 75 | BA9: 75 | BB9: 75 | BC9: 75 | BD9: 75 | BE9: 75 | BF9: 75 | BG9: 75 | BH9: 75 | BI9: 75 | BJ9: 75 | BK9: 75 | BL9: 75 | BM9: 75
A10: 75 | B10: 75 | C10: 75 | D10: 75 | E10: 75 | F10: 75 | G10: 75 | H10: 75 | I10: 75 | J10: 75 | K10: 75 | L10: 75 | M10: 75 | N10: 75 | O10: 75 | P10: 75 | Q10: 75 | R10: 75 | S10: 75 | T10: 75 | U10: 75 | V10: 75 | W10: 75 | X10: 75 | Y10: 75 | Z10: 75 | AA10: 75 | AB10: 75 | AC10: 75 | AD10: 75 | AE10: 75 | AF10: 75 | AG10: 75 | AH10: 75 | AI10: 75 | AJ10: 75 | AK10: 75 | AL10: 75 | AM10: 75 | AN10: 75 | AO10: 75 | AP10: 75 | AQ10: 75 | AR10: 75 | AS10: 75 | AT10: 75 | AU10: 75 | AV10: 75 | AW10: 75 | AX10: 75 | AY10: 75 | AZ10: 75 | BA10: 75 | BB10: 75 | BC10: 75 | BD10: 75 | BE10: 75 | BF10: 75 | BG10: 75 | BH10: 75 | BI10: 75 | BJ10: 75 | BK10: 75 | BL10: 75 | BM10: 75
A11: 75 | B11: 75 | C11: 75 | D11: 75 | E11: 75 | F11: 75 | G11: 75 | H11: 75 | I11: 75 | J11: 75 | K11: 75 | L11: 75 | M11: 75 | N11: 75 | O11: 75 | P11: 75 | Q11: 75 | R11: 75 | S11: 75 | T11: 75 | U11: 75 | V11: 75 | W11: 75 | X11: 75 | Y11: 75 | Z11: 75 | AA11: 75 | AB11: 75 | AC11: 75 | AD11: 75 | AE11: 75 | AF11: 75 | AG11: 75 | AH11: 75 | AI11: 75 | AJ11: 75 | AK11: 75 | AL11: 75 | AM11: 75 | AN11: 75 | AO11: 75 | AP11: 75 | AQ11: 75 | AR11: 75 | AS11: 75 | AT11: 75 | AU11: 75 | AV11: 75 | AW11: 75 | AX11: 75 | AY11: 75 | AZ11: 75 | BA11: 75 | BB11: 75 | BC11: 75 | BD11: 75 | BE11: 75 | BF11: 75 | BG11: 75 | BH11: 75 | BI11: 75 | BJ11: 75 | BK11: 75 | BL11: 75 | BM11: 75
A12: 75 | B12: 75 | C12: 75 | D12: 75 | E12: 75 | F12: 75 | G12: 75 | H12: 75 | I12: 75 | J12: 75 | K12: 75 | L12: 75 | M12: 75 | N12: 75 | O12: 75 | P12: 75 | Q12: 75 | R12: 75 | S12: 75 | T12: 75 | U12: 75 | V12: 75 | W12: 75 | X12: 75 | Y12: 75 | Z12: 75 | AA12: 75 | AB12: 75 | AC12: 75 | AD12: 75 | AE12: 75 | AF12: 75 | AG12: 75 | AH12: 75 | AI12: 75 | AJ12: 75 | AK12: 75 | AL12: 75 | AM12: 75 | AN12: 75 | AO12: 75 | AP12: 75 | AQ12: 75 | AR12: 75 | AS12: 75 | AT12: 75 | AU12: 75 | AV12: 75 | AW12: 75 | AX12: 75 | AY12: 75 | AZ12: 75 | BA12: 75 | BB12: 75 | BC12: 75 | BD12: 75 | BE12: 75 | BF12: 75 | BG12: 75 | BH12: 75 | BI12: 75 | BJ12: 75 | BK12: 75 | BL12: 75 | BM12: 75
... A65: 75 | B65: 75 | C65: 75 | D65: 75 | E65: 75 | F65: 75 | G65: 75 | H65: 75 | I65: 75 | J65: 75 | K65: 75 | L65: 75 | M65: 75 | N65: 75 | O65: 75 | P65: 75 | Q65: 75 | R65: 75 | S65: 75 | T65: 75 | U65: 75 | V65: 75 | W65: 75 | X65: 75 | Y65: 75 | Z65: 75 | AA65: 75 | AB65: 75 | AC65: 75 | AD65: 75 | AE65: 75 | AF65: 75 | AG65: 75 | AH65: 75 | AI65: 75 | AJ65: 75 | AK65: 75 | AL65: 75 | AM65: 75 | AN65: 75 | AO65: 75 | AP65: 75 | AQ65: 75 | AR65: 75 | AS65: 75 | AT65: 75 | AU65: 75 | AV65: 75 | AW65: 75 | AX65: 75 | AY65: 75 | AZ65: 75 | BA65: 75 | BB65: 75 | BC65: 75 | BD65: 75 | BE65: 75 | BF65: 75 | BG65: 75 | BH65: 75 | BI65: 75 | BJ65: 75 | BK65: 75 | BL65: 75 | BM65: 75

Sheet Plate_3b
A1: 60 | B1: 100 | C1: 100 | D1: 100 | E1: 100 | F1: 100 | G1: 100 | H1: 100 | I1: 100 | J1: 100 | K1: 100 | L1: 100 | M1: 100 | N1: 100 | O1: 100 | P1: 100 | Q1: 100 | R1: 100 | S1: 100 | T1: 100 | U1: 100 | V1: 100 | W1: 100 | X1: 100 | Y1: 100 | Z1: 100 | AA1: 100 | AB1: 100 | AC1: 100 | AD1: 100 | AE1: 100 | AF1: 100 | AG1: 100 | AH1: 100 | AI1: 100 | AJ1: 100 | AK1: 100 | AL1: 100 | AM1: 100 | AN1: 100 | AO1: 100 | AP1: 100 | AQ1: 100 | AR1: 100 | AS1: 100 | AT1: 100 | AU1: 100 | AV1: 100 | AW1: 100 | AX1: 100 | AY1: 100 | AZ1: 100 | BA1: 100 | BB1: 100 | BC1: 100 | BD1: 100 | BE1: 100 | BF1: 100 | BG1: 100 | BH1: 100 | BI1: 100 | BJ1: 100 | BK1: 100 | BL1: 100 | BM1: 50
A2: 20 | B2: 59.9786 | C2: 75.7694 | D2: 83.1845 | E2: 87.2343 | F2: 89.7219 | G2: 91.3873 | H2: 92.5739 | I2: 93.459 | J2: 94.1423 | K2: 94.6837 | L2: 95.1219 | M2: 95.4822 | N2: 95.7824 | O2: 96.0352 | P2: 96.2497 | Q2: 96.4329 | R2: 96.5901 | S2: 96.7253 | T2: 96.8416 | U2: 96.9417 | V2: 97.0275 | W2: 97.1007 | X2: 97.1625 | Y2: 97.2141 | Z2: 97.2562 | AA2: 97.2895 | AB2: 97.3147 | AC2: 97.3321 | AD2: 97.342 | AE2: 97.3446 | AF2: 97.3401 | AG2: 97.3286 | AH2: 97.3099 | AI2: 97.284 | AJ2: 97.2506 | AK2: 97.2095 | AL2: 97.1604 | AM2: 97.1026 | AN2: 97.0355 | AO2: 96.9585 | AP2: 96.8705 | AQ2: 96.7705 | AR2: 96.657 | AS2: 96.5284 | AT2: 96.3826 | AU2: 96.2169 | AV2: 96.0283 | AW2: 95.8126 | AX2: 95.5648 | AY2: 95.2782 | AZ2: 94.9442 | BA2: 94.5512 | BB2: 94.0833 | BC2: 93.5185 | BD2: 92.8246 | BE2: 91.9538 | BF2: 90.8308 | BG2: 89.331 | BH2: 87.2329 | BI2: 84.1072 | BJ2: 79.0288 | BK2: 69.7438 | BL2: 49.9893 | BM2: 0
A3: 20 | B3: 44.1451 | C3: 59.9145 | D3: 69.7343 | E3: 76.0307 | F3: 80.2659 | G3: 83.2533 | H3: 85.4494 | I3: 87.1199 | J3: 88.4262 | K3: 89.4709 | L3: 90.3215 | M3: 91.0244 | N3: 91.6122 | O3: 92.1085 | P3: 92.5307 | Q3: 92.8919 | R3: 93.2021 | S3: 93.4693 | T3: 93.6995 | U3: 93.8977 | V3: 94.0677 | W3: 94.2127 | X3: 94.3353 | Y3: 94.4376 | Z3: 94.5211 | AA3: 94.5873 | AB3: 94.6372 | AC3: 94.6716 | AD3: 94.6912 | AE3: 94.6964 | AF3: 94.6874 | AG3: 94.6643 | AH3: 94.627 | AI3: 94.5754 | AJ3: 94.509 | AK3: 94.4272 | AL3: 94.3293 | AM3: 94.2143 | AN3: 94.081 | AO3: 93.9279 | AP3: 93.7531 | AQ3: 93.5545 | AR3: 93.3292 | AS3: 93.0741 | AT3: 92.7849 | AU3: 92.4568 | AV3: 92.0836 | AW3: 91.6574 | AX3: 91.1683 | AY3: 90.6038 | AZ3: 89.9474 | BA3: 89.1772 | BB3: 88.2636 | BC3: 87.1659 | BD3: 85.8262 | BE3: 84.1597 | BF3: 82.0384 | BG3: 79.2603 | BH3: 75.4934 | BI3: 70.167 | BJ3: 62.2642 | BK3: 49.9572 | BL3: 30.2134 | BM3: 0
A4: 20 | B4: 36.6872 | C4: 50.0091 | D4: 59.8076 | E4: 66.8885 | F4: 72.0576 | G4: 75.9106 | H4: 78.8506 | I4: 81.145 | J4: 82.9719 | K4: 84.452 | L4: 85.6688 | M4: 86.6818 | N4: 87.5336 | O4: 88.256 | P4: 88.8727 | Q4: 89.4018 | R4: 89.8573 | S4: 90.2503 | T4: 90.5895 | U4: 90.8818 | V4: 91.1329 | W4: 91.3472 | X4: 91.5285 | Y4: 91.6798 | Z4: 91.8034 | AA4: 91.9013 | AB4: 91.9752 | AC4: 92.026 | AD4: 92.0549 | AE4: 92.0623 | AF4: 92.0487 | AG4: 92.0141 | AH4: 91.9585 | AI4: 91.8816 | AJ4: 91.7827 | AK4: 91.661 | AL4: 91.5154 | AM4: 91.3444 | AN4: 91.1464 | AO4: 90.919 | AP4: 90.6596 | AQ4: 90.3651 | AR4: 90.0313 | AS4: 89.6537 | AT4: 89.2263 | AU4: 88.7419 | AV4: 88.1918 | AW4: 87.5649 | AX4: 86.8473 | AY4: 86.0214 | AZ4: 85.0644 | BA4: 83.9465 | BB4: 82.628 | BC4: 81.0554 | BD4: 79.1545 | BE4: 76.8206 | BF4: 73.9028 | BG4: 70.1784 | BH4: 65.3133 | BI4: 58.8033 | BJ4: 49.9038 | BK4: 37.6075 | BL4: 20.9071 | BM4: 0
A5: 20 | B5: 32.5947 | C5: 43.6272 | D5: 52.5985 | E5: 59.658 | F5: 65.1655 | G5: 69.4807 | H5: 72.8975 | I5: 75.6377 | J5: 77.8644 | K5: 79.6962 | L5: 81.2201 | M5: 82.5002 | N5: 83.5845 | O5: 84.5092 | P5: 85.3022 | Q5: 85.9852 | R5: 86.575 | S5: 87.0851 | T5: 87.5263 | U5: 87.9072 | V5: 88.2347 | W5: 88.5147 | X5: 88.7517 | Y5: 88.9496 | Z5: 89.1114 | AA5: 89.2395 | AB5: 89.3361 | AC5: 89.4025 | AD5: 89.44 | AE5: 89.4493 | AF5: 89.4309 | AG5: 89.385 | AH5: 89.3114 | AI5: 89.2097 | AJ5: 89.0792 | AK5: 88.9187 | AL5: 88.7268 | AM5: 88.5016 | AN5: 88.241 | AO5: 87.942 | AP5: 87.6013 | AQ5: 87.2148 | AR5: 86.7774 | AS5: 86.2831 | AT5: 85.7245 | AU5: 85.0928 | AV5: 84.3769 | AW5: 83.5631 | AX5: 82.6347 | AY5: 81.5701 | AZ5: 80.3423 | BA5: 78.9163 | BB5: 77.2466 | BC5: 75.2732 | BD5: 72.9156 | BE5: 70.0654 | BF5: 66.5739 | BG5: 62.2373 | BH5: 56.7781 | BI5: 49.829 | BJ5: 40.9402 | BK5: 29.662 | BL5: 15.8073 | BM5: 0
A6: 20 | B6: 30.0644 | C6: 39.3066 | D6: 47.3011 | E6: 53.9794 | F6: 59.4656 | G6: 63.9494 | H6: 67.6208 | I6: 70.6439 | J6: 73.1517 | K6: 75.2485 | L6: 77.0152 | M6: 78.5145 | N6: 79.7949 | O6: 80.8941 | P6: 81.8419 | Q6: 82.6618 | R6: 83.3724 | S6: 83.9889 | T6: 84.5234 | U6: 84.9858 | V6: 85.3842 | W6: 85.7252 | X6: 86.0141 | Y6: 86.2555 | Z6: 86.4529 | AA6: 86.6093 | AB6: 86.727 | AC6: 86.8079 | AD6: 86.8532 | AE6: 86.8639 | AF6: 86.8407 | AG6: 86.7836 | AH6: 86.6924 | AI6: 86.5668 | AJ6: 86.4056 | AK6: 86.2078 | AL6: 85.9714 | AM6: 85.6944 | AN6: 85.374 | AO6: 85.0068 | AP6: 84.5889 | AQ6: 84.1153 | AR6: 83.5803 | AS6: 82.9767 | AT6: 82.296 | AU6: 81.5279 | AV6: 80.6597 | AW6: 79.6761 | AX6: 78.5581 | AY6: 77.282 | AZ6: 75.8184 | BA6: 74.1298 | BB6: 72.169 | BC6: 69.875 | BD6: 67.1696 | BE6: 63.9514 | BF6: 60.0899 | BG6: 55.4188 | BH6: 49.7328 | BI6: 42.7944 | BJ6: 34.366 | BK6: 24.2928 | BL6: 12.6602 | BM6: 0
A7: 20 | B7: 28.3562 | C7: 36.2336 | D7: 43.3198 | E7: 49.4932 | F7: 54.768 | G7: 59.2305 | H7: 62.9924 | I7: 66.1655 | J7: 68.8499 | K7: 71.1308 | L7: 73.0778 | M7: 74.7478 | N7: 76.1864 | O7: 77.4304 | P7: 78.5095 | Q7: 79.4475 | R7: 80.264 | S7: 80.9747 | T7: 81.5927 | U7: 82.1285 | V7: 82.5911 | W7: 82.9877 | X7: 83.3241 | Y7: 83.6054 | Z7: 83.8355 | AA7: 84.0178 | AB7: 84.1549 | AC7: 84.2488 | AD7: 84.301 | AE7: 84.3126 | AF7: 84.2843 | AG7: 84.2161 | AH7: 84.108 | AI7: 83.9592 | AJ7: 83.7688 | AK7: 83.5353 | AL7: 83.2567 | AM7: 82.9305 | AN7: 82.5536 | AO7: 82.1223 | AP7: 81.6321 | AQ7: 81.0774 | AR7: 80.4518 | AS7: 79.7474 | AT7: 78.9549 | AU7: 78.0629 | AV7: 77.058 | AW7: 75.9236 | AX7: 74.6396 | AY7: 73.1816 | AZ7: 71.5193 | BA7: 69.6157 | BB7: 67.4244 | BC7: 64.8883 | BD7: 61.9363 | BE7: 58.4808 | BF7: 54.4156 | BG7: 49.6152 | BH7: 43.9399 | BI7: 37.2496 | BJ7: 29.4368 | BK7: 20.4831 | BL7: 10.5407 | BM7: 0
A8: 20 | B8: 27.1267 | C8: 33.9519 | D8: 40.2514 | E8: 45.9054 | F8: 50.8829 | G8: 55.2122 | H8: 58.9527 | I8: 62.1756 | J8: 64.9519 | K8: 67.3468 | L8: 69.4174 | M8: 71.2124 | N8: 72.7725 | O8: 74.1317 | P8: 75.3181 | Q8: 76.3548 | R8: 77.2612 | S8: 78.0532 | T8: 78.744 | U8: 79.3446 | V8: 79.8641 | W8: 80.3102 | X8: 80.6892 | Y8: 81.0064 | Z8: 81.266 | AA8: 81.4716 | AB8: 81.626 | AC8: 81.7314 | AD8: 81.7894 | AE8: 81.8013 | AF8: 81.7676 | AG8: 81.6887 | AH8: 81.5641 | AI8: 81.3934 | AJ8: 81.1752 | AK8: 80.908 | AL8: 80.5896 | AM8: 80.2173 | AN8: 79.7878 | AO8: 79.2968 | AP8: 78.7397 | AQ8: 78.1104 | AR8: 77.402 | AS8: 76.6062 | AT8: 75.7132 | AU8: 74.711 | AV8: 73.5857 | AW8: 72.3205 | AX8: 70.8951 | AY8: 69.2853 | AZ8: 67.4618 | BA8: 65.3891 | BB8: 63.0248 | BC8: 60.3175 | BD8: 57.2064 | BE8: 53.6199 | BF8: 49.4764 | BG8: 44.6867 | BH8: 39.1619 | BI8: 32.8276 | BJ8: 25.6482 | BK8: 17.6623 | BL8: 9.0195 | BM8: 0
A9: 20 | B9: 26.1988 | C9: 32.1958 | D9: 37.8287 | E9: 42.994 | F9: 47.6459 | G9: 51.7826 | H9: 55.4308 | I9: 58.6324 | J9: 61.4352 | K9: 63.8871 | L9: 66.0327 | M9: 67.9119 | N9: 69.5596 | O9: 71.0059 | P9: 72.2763 | Q9: 73.3925 | R9: 74.3729 | S9: 75.2329 | T9: 75.9855 | U9: 76.6416 | V9: 77.2105 | W9: 77.6999 | X9: 78.1162 | Y9: 78.4649 | Z9: 78.7504 | AA9: 78.9765 | AB9: 79.146 | AC9: 79.2613 | AD9: 79.324 | AE9: 79.3355 | AF9: 79.2963 | AG9: 79.2068 | AH9: 79.0665 | AI9: 78.8749 | AJ9: 78.6305 | AK9: 78.3318 | AL9: 77.9764 | AM9: 77.5614 | AN9: 77.0832 | AO9: 76.5376 | AP9: 75.9194 | AQ9: 75.2225 | AR9: 74.4397 | AS9: 73.5624 | AT9: 72.5805 | AU9: 71.4822 | AV9: 70.2535 | AW9: 68.8776 | AX9: 67.3351 | AY9: 65.6028 | AZ9: 63.6532 | BA9: 61.4542 | BB9: 58.968 | BC9: 56.1506 | BD9: 52.952 | BE9: 49.3162 | BF9: 45.1832 | BG9: 40.4932 | BH9: 35.1935 | BI9: 29.2505 | BJ9: 22.6662 | BK9: 15.4981 | BL9: 7.8751 | BM9: 0
A10: 20 | B10: 25.4728 | C10: 30.8039 | D10: 35.8733 | E10: 40.5961 | F10: 44.9243 | G10: 48.8416 | H10: 52.3553 | I10: 55.4878 | J10: 58.2695 | K10: 60.7338 | L10: 62.9144 | M10: 64.8429 | N10: 66.5481 | O10: 68.0559 | P10: 69.3886 | Q10: 70.5661 | R10: 71.605 | S10: 72.52 | T10: 73.3235 | U10: 74.0259 | V10: 74.6364 | W10: 75.1625 | X10: 75.6108 | Y10: 75.9866 | Z10: 76.2944 | AA10: 76.538 | AB10: 76.7203 | AC10: 76.8437 | AD10: 76.91 | AE10: 76.9203 | AF10: 76.8755 | AG10: 76.7756 | AH10: 76.6204 | AI10: 76.409 | AJ10: 76.1403 | AK10: 75.8124 | AL10: 75.4228 | AM10: 74.9686 | AN10: 74.4461 | AO10: 73.851 | AP10: 73.1778 | AQ10: 72.4205 | AR10: 71.5718 | AS10: 70.623 | AT10: 69.5643 | AU10: 68.3839 | AV10: 67.0682 | AW10: 65.6014 | AX10: 63.965 | AY10: 62.1375 | AZ10: 60.0942 | BA10: 57.8066 | BB10: 55.2423 | BC10: 52.3649 | BD10: 49.1347 | BE10: 45.5095 | BF10: 41.4472 | BG10: 36.9095 | BH10: 31.8684 | BI10: 26.3146 | BJ10: 20.2682 | BK10: 13.7889 | BL10: 6.9829 | BM10: 0
A11: 20 | B11: 24.8884 | C11: 29.6735 | D11: 34.2647 | E11: 38.5929 | F11: 42.6134 | G11: 46.304 | H11: 49.6611 | I11: 52.6942 | J11: 55.4211 | K11: 57.8643 | L11: 60.0481 | M11: 61.997 | N11: 63.7341 | O11: 65.2808 | P11: 66.6564 | Q11: 67.8781 | R11: 68.9611 | S11: 69.9187 | T11: 70.7624 | U11: 71.5022 | V11: 72.1466 | W11: 72.7031 | X11: 73.1779 | Y11: 73.5762 | Z11: 73.9026 | AA11: 74.1607 | AB11: 74.3535 | AC11: 74.4832 | AD11: 74.5518 | AE11: 74.5604 | AF11: 74.5096 | AG11: 74.3997 | AH11: 74.2303 | AI11: 74.0006 | AJ11: 73.7093 | AK11: 73.3545 | AL11: 72.9338 | AM11: 72.4441 | AN11: 71.8817 | AO11: 71.2423 | AP11: 70.5204 | AQ11: 69.71 | AR11: 68.8039 | AS11: 67.7937 | AT11: 66.6698 | AU11: 65.4209 | AV11: 64.0342 | AW11: 62.4948 | AX11: 60.7859 | AY11: 58.888 | AZ11: 56.7795 | BA11: 54.4357 | BB11: 51.8296 | BC11: 48.9321 | BD11: 45.7125 | BE11: 42.1401 | BF11: 38.1864 | BG11: 33.8291 | BH11: 29.0559 | BI11: 23.8714 | BJ11: 18.303 | BK11: 12.4063 | BL11: 6.2676 | BM11: 0
A12: 20 | B12: 24.4074 | C12: 28.737 | D12: 32.9191 | E12: 36.8975 | F12: 40.6324 | G12: 44.1001 | H12: 47.291 | I12: 50.2067 | J12: 52.8563 | K12: 55.254 | L12: 57.4169 | M12: 59.363 | N12: 61.1106 | O12: 62.6768 | P12: 64.078 | Q12: 65.3288 | R12: 66.4426 | S12: 67.4313 | T12: 68.3053 | U12: 69.0738 | V12: 69.7449 | W12: 70.3254 | X12: 70.8214 | Y12: 71.2378 | Z12: 71.5791 | AA12: 71.8487 | AB12: 72.0496 | AC12: 72.184 | AD12: 72.2537 | AE12: 72.2597 | AF12: 72.2029 | AG12: 72.0832 | AH12: 71.9005 | AI12: 71.6538 | AJ12: 71.3418 | AK12: 70.9626 | AL12: 70.5138 | AM12: 69.9923 | AN12: 69.3945 | AO12: 68.7159 | AP12: 67.9515 | AQ12: 67.0952 | AR12: 66.1401 | AS12: 65.0782 | AT12: 63.9002 | AU12: 62.5957 | AV12: 61.1527 | AW12: 59.5578 | AX12: 57.7956 | AY12: 55.8493 | AZ12: 53.6999 | BA12: 51.327 | BB12: 48.7084 | BC12: 45.8214 | BD12: 42.6431 | BE12: 39.1517 | BF12: 35.3295 | BG12: 31.1645 | BH12: 26.6548 | BI12: 21.8122 | BJ12: 16.666 | BK12: 11.2657 | BL12: 5.6813 | BM12: 0
... A65: 30 | B65: 40 | C65: 40 | D65: 40 | E65: 40 | F65: 40 | G65: 40 | H65: 40 | I65: 40 | J65: 40 | K65: 40 | L65: 40 | M65: 40 | N65: 40 | O65: 40 | P65: 40 | Q65: 40 | R65: 40 | S65: 40 | T65: 40 | U65: 40 | V65: 40 | W65: 40 | X65: 40 | Y65: 40 | Z65: 40 | AA65: 40 | AB65: 40 | AC65: 40 | AD65: 40 | AE65: 40 | AF65: 40 | AG65: 40 | AH65: 40 | AI65: 40 | AJ65: 40 | AK65: 40 | AL65: 40 | AM65: 40 | AN65: 40 | AO65: 40 | AP65: 40 | AQ65: 40 | AR65: 40 | AS65: 40 | AT65: 40 | AU65: 40 | AV65: 40 | AW65: 40 | AX65: 40 | AY65: 40 | AZ65: 40 | BA65: 40 | BB65: 40 | BC65: 40 | BD65: 40 | BE65: 40 | BF65: 40 | BG65: 40 | BH65: 40 | BI65: 40 | BJ65: 40 | BK65: 40 | BL65: 40 | BM65: 20

Sheet Plate_3c
A1: 50 | B1: 100 | C1: 100 | D1: 100 | E1: 100 | F1: 100 | G1: 100 | H1: 100 | I1: 100 | J1: 100 | K1: 100 | L1: 100 | M1: 100 | N1: 100 | O1: 100 | P1: 100 | Q1: 100 | R1: 100 | S1: 100 | T1: 100 | U1: 100 | V1: 100 | W1: 100 | X1: 100 | Y1: 100 | Z1: 100 | AA1: 100 | AB1: 100 | AC1: 100 | AD1: 100 | AE1: 100 | AF1: 100 | AG1: 100 | AH1: 100 | AI1: 100 | AJ1: 100 | AK1: 100 | AL1: 100 | AM1: 100 | AN1: 100 | AO1: 100 | AP1: 100 | AQ1: 100 | AR1: 100 | AS1: 100 | AT1: 100 | AU1: 100 | AV1: 100 | AW1: 100 | AX1: 100 | AY1: 100 | AZ1: 100 | BA1: 100 | BB1: 100 | BC1: 100 | BD1: 100 | BE1: 100 | BF1: 100 | BG1: 100 | BH1: 100 | BI1: 100 | BJ1: 100 | BK1: 100 | BL1: 100 | BM1: 50
A2: 0 | B2: 49.9733 | C2: 69.7118 | D2: 78.9808 | E2: 84.0432 | F2: 87.153 | G2: 89.2353 | H2: 90.7193 | I2: 91.8266 | J2: 92.6819 | K2: 93.3602 | L2: 93.9097 | M2: 94.3623 | N2: 94.7402 | O2: 95.0593 | P2: 95.331 | Q2: 95.5641 | R2: 95.7651 | S2: 95.9393 | T2: 96.0906 | U2: 96.2221 | V2: 96.3366 | W2: 96.436 | X2: 96.5219 | Y2: 96.5959 | Z2: 96.6589 | AA2: 96.712 | AB2: 96.7557 | AC2: 96.7908 | AD2: 96.8176 | AE2: 96.8366 | AF2: 96.8478 | AG2: 96.8516 | AH2: 96.8478 | AI2: 96.8366 | AJ2: 96.8176 | AK2: 96.7908 | AL2: 96.7557 | AM2: 96.712 | AN2: 96.6589 | AO2: 96.5959 | AP2: 96.5219 | AQ2: 96.436 | AR2: 96.3366 | AS2: 96.2221 | AT2: 96.0906 | AU2: 95.9393 | AV2: 95.7651 | AW2: 95.5641 | AX2: 95.331 | AY2: 95.0593 | AZ2: 94.7402 | BA2: 94.3623 | BB2: 93.9097 | BC2: 93.3602 | BD2: 92.6819 | BE2: 91.8266 | BF2: 90.7193 | BG2: 89.2353 | BH2: 87.153 | BI2: 84.0432 | BJ2: 78.9808 | BK2: 69.7118 | BL2: 49.9733 | BM2: 0
A3: 0 | B3: 30.1813 | C3: 49.8931 | D3: 62.1681 | E3: 70.039 | F3: 75.3335 | G3: 79.0688 | H3: 81.8153 | I3: 83.9053 | J3: 85.5406 | K3: 86.8493 | L3: 87.9163 | M3: 88.7994 | N3: 89.5394 | O3: 90.1658 | P3: 90.7006 | Q3: 91.1602 | R3: 91.5572 | S3: 91.9015 | T3: 92.2008 | U3: 92.4614 | V3: 92.6882 | W3: 92.8853 | X3: 93.0559 | Y3: 93.2027 | Z3: 93.3279 | AA3: 93.4332 | AB3: 93.5202 | AC3: 93.5899 | AD3: 93.6432 | AE3: 93.6808 | AF3: 93.7032 | AG3: 93.7107 | AH3: 93.7032 | AI3: 93.6808 | AJ3: 93.6432 | AK3: 93.5899 | AL3: 93.5202 | AM3: 93.4332 | AN3: 93.3279 | AO3: 93.2027 | AP3: 93.0559 | AQ3: 92.8853 | AR3: 92.6882 | AS3: 92.4614 | AT3: 92.2008 | AU3: 91.9015 | AV3: 91.5572 | AW3: 91.1602 | AX3: 90.7006 | AY3: 90.1658 | AZ3: 89.5394 | BA3: 88.7994 | BB3: 87.9163 | BC3: 86.8493 | BD3: 85.5406 | BE3: 83.9053 | BF3: 81.8153 | BG3: 79.0688 | BH3: 75.3335 | BI3: 70.039 | BJ3: 62.1681 | BK3: 49.8931 | BL3: 30.1813 | BM3: 0
A4: 0 | B4: 20.8589 | C4: 37.5112 | D4: 49.7595 | E4: 58.6111 | F4: 65.0733 | G4: 69.8909 | H4: 73.568 | I4: 76.4387 | J4: 78.7258 | K4: 80.5803 | L4: 82.1068 | M4: 83.3795 | N4: 84.4521 | O4: 85.3641 | P4: 86.1454 | Q4: 86.8188 | R4: 87.4019 | S4: 87.9086 | T4: 88.3498 | U4: 88.7345 | V4: 89.0696 | W4: 89.3611 | X4: 89.6137 | Y4: 89.8311 | Z4: 90.0167 | AA4: 90.1729 | AB4: 90.3019 | AC4: 90.4053 | AD4: 90.4844 | AE4: 90.5403 | AF4: 90.5736 | AG4: 90.5846 | AH4: 90.5736 | AI4: 90.5403 | AJ4: 90.4844 | AK4: 90.4053 | AL4: 90.3019 | AM4: 90.1729 | AN4: 90.0167 | AO4: 89.8311 | AP4: 89.6137 | AQ4: 89.3611 | AR4: 89.0696 | AS4: 88.7345 | AT4: 88.3498 | AU4: 87.9086 | AV4: 87.4019 | AW4: 86.8188 | AX4: 86.1454 | AY4: 85.3641 | AZ4: 84.4521 | BA4: 83.3795 | BB4: 82.1068 | BC4: 80.5803 | BD4: 78.7258 | BE4: 76.4387 | BF4: 73.568 | BG4: 69.8909 | BH4: 65.0733 | BI4: 58.6111 | BJ4: 49.7595 | BK4: 37.5112 | BL4: 20.8589 | BM4: 0
A5: 0 | B5: 15.743 | C5: 29.5335 | D5: 40.7476 | E5: 49.5725 | F5: 56.4578 | G5: 61.8536 | H5: 66.127 | I5: 69.5557 | J5: 72.3436 | K5: 74.6391 | L5: 76.5511 | M5: 78.1598 | N5: 79.5253 | O5: 80.6931 | P5: 81.6982 | Q5: 82.5678 | R5: 83.3231 | S5: 83.9811 | T5: 84.5554 | U5: 85.057 | V5: 85.4947 | W5: 85.8759 | X5: 86.2065 | Y5: 86.4915 | Z5: 86.7348 | AA5: 86.9398 | AB5: 87.1091 | AC5: 87.245 | AD5: 87.349 | AE5: 87.4224 | AF5: 87.4661 | AG5: 87.4806 | AH5: 87.4661 | AI5: 87.4224 | AJ5: 87.349 | AK5: 87.245 | AL5: 87.1091 | AM5: 86.9398 | AN5: 86.7348 | AO5: 86.4915 | AP5: 86.2065 | AQ5: 85.8759 | AR5: 85.4947 | AS5: 85.057 | AT5: 84.5554 | AU5: 83.9811 | AV5: 83.3231 | AW5: 82.5678 | AX5: 81.6982 | AY5: 80.6931 | AZ5: 79.5253 | BA5: 78.1598 | BB5: 76.5511 | BC5: 74.6391 | BD5: 72.3436 | BE5: 69.5557 | BF5: 66.127 | BG5: 61.8536 | BH5: 56.4578 | BI5: 49.5725 | BJ5: 40.7476 | BK5: 29.5335 | BL5: 15.743 | BM5: 0
A6: 0 | B6: 12.5798 | C6: 24.132 | D6: 34.125 | E6: 42.4733 | F6: 49.332 | G6: 54.9386 | H6: 59.5307 | I6: 63.3136 | J6: 66.4537 | K6: 69.0816 | L6: 71.2987 | M6: 73.1832 | N6: 74.7961 | O6: 76.1848 | P6: 77.3865 | Q6: 78.4309 | R6: 79.3415 | S6: 80.1374 | T6: 80.8338 | U6: 81.4434 | V6: 81.9764 | W6: 82.4413 | X6: 82.845 | Y6: 83.1934 | Z6: 83.4912 | AA6: 83.7423 | AB6: 83.9499 | AC6: 84.1165 | AD6: 84.2441 | AE6: 84.3342 | AF6: 84.3878 | AG6: 84.4057 | AH6: 84.3878 | AI6: 84.3342 | AJ6: 84.2441 | AK6: 84.1165 | AL6: 83.9499 | AM6: 83.7423 | AN6: 83.4912 | AO6: 83.1934 | AP6: 82.845 | AQ6: 82.4413 | AR6: 81.9764 | AS6: 81.4434 | AT6: 80.8338 | AU6: 80.1374 | AV6: 79.3415 | AW6: 78.4309 | AX6: 77.3865 | AY6: 76.1848 | AZ6: 74.7961 | BA6: 73.1832 | BB6: 71.2987 | BC6: 69.0816 | BD6: 66.4537 | BE6: 63.3136 | BF6: 59.5307 | BG6: 54.9386 | BH6: 49.332 | BI6: 42.4733 | BJ6: 34.125 | BK6: 24.132 | BL6: 12.5798 | BM6: 0
A7: 0 | B7: 10.444 | C7: 20.2899 | D7: 29.1471 | E7: 36.8638 | F7: 43.4582 | G7: 49.0381 | H7: 53.7435 | I7: 57.7144 | J7: 61.0761 | K7: 63.935 | L7: 66.3787 | M7: 68.4783 | N7: 70.2912 | O7: 71.8634 | P7: 73.2323 | Q7: 74.4279 | R7: 75.4748 | S7: 76.393 | T7: 77.199 | U7: 77.9063 | V7: 78.5261 | W7: 79.0677 | X7: 79.5389 | Y7: 79.946 | Z7: 80.2944 | AA7: 80.5884 | AB7: 80.8316 | AC7: 81.027 | AD7: 81.1767 | AE7: 81.2824 | AF7: 81.3454 | AG7: 81.3663 | AH7: 81.3454 | AI7: 81.2824 | AJ7: 81.1767 | AK7: 81.027 | AL7: 80.8316 | AM7: 80.5884 | AN7: 80.2944 | AO7: 79.946 | AP7: 79.5389 | AQ7: 79.0677 | AR7: 78.5261 | AS7: 77.9063 | AT7: 77.199 | AU7: 76.393 | AV7: 75.4748 | AW7: 74.4279 | AX7: 73.2323 | AY7: 71.8634 | AZ7: 70.2912 | BA7: 68.4783 | BB7: 66.3787 | BC7: 63.935 | BD7: 61.0761 | BE7: 57.7144 | BF7: 53.7435 | BG7: 49.0381 | BH7: 43.4582 | BI7: 36.8638 | BJ7: 29.1471 | BK7: 20.2899 | BL7: 10.444 | BM7: 0
A8: 0 | B8: 8.9065 | C8: 17.4363 | D8: 25.3096 | E8: 32.3765 | F8: 38.5989 | G8: 44.0122 | H8: 48.6909 | I8: 52.7242 | J8: 56.2012 | K8: 59.2035 | L8: 61.8029 | M8: 64.0602 | N8: 66.0269 | O8: 67.7454 | P8: 69.2512 | Q8: 70.5735 | R8: 71.7367 | S8: 72.7609 | T8: 73.6629 | U8: 74.4567 | V8: 75.154 | W8: 75.7647 | X8: 76.2968 | Y8: 76.7573 | Z8: 77.1519 | AA8: 77.4853 | AB8: 77.7613 | AC8: 77.9831 | AD8: 78.1532 | AE8: 78.2734 | AF8: 78.3451 | AG8: 78.3689 | AH8: 78.3451 | AI8: 78.2734 | AJ8: 78.1532 | AK8: 77.9831 | AL8: 77.7613 | AM8: 77.4853 | AN8: 77.1519 | AO8: 76.7573 | AP8: 76.2968 | AQ8: 75.7647 | AR8: 75.154 | AS8: 74.4567 | AT8: 73.6629 | AU8: 72.7609 | AV8: 71.7367 | AW8: 70.5735 | AX8: 69.2512 | AY8: 67.7454 | AZ8: 66.0269 | BA8: 64.0602 | BB8: 61.8029 | BC8: 59.2035 | BD8: 56.2012 | BE8: 52.7242 | BF8: 48.6909 | BG8: 44.0122 | BH8: 38.5989 | BI8: 32.3765 | BJ8: 25.3096 | BK8: 17.4363 | BL8: 8.9065 | BM8: 0
A9: 0 | B9: 7.7457 | C9: 15.2394 | D9: 22.2784 | E9: 28.7339 | F9: 34.5487 | G9: 39.7207 | H9: 44.2837 | I9: 48.2904 | J9: 51.8009 | K9: 54.8751 | L9: 57.569 | M9: 59.9329 | N9: 62.0107 | O9: 63.8401 | P9: 65.4536 | Q9: 66.8783 | R9: 68.1376 | S9: 69.251 | T9: 70.235 | U9: 71.1036 | V9: 71.8686 | W9: 72.5401 | X9: 73.1264 | Y9: 73.6346 | Z9: 74.0706 | AA9: 74.4394 | AB9: 74.7451 | AC9: 74.991 | AD9: 75.1797 | AE9: 75.3131 | AF9: 75.3925 | AG9: 75.4189 | AH9: 75.3925 | AI9: 75.3131 | AJ9: 75.1797 | AK9: 74.991 | AL9: 74.7451 | AM9: 74.4394 | AN9: 74.0706 | AO9: 73.6346 | AP9: 73.1264 | AQ9: 72.5401 | AR9: 71.8686 | AS9: 71.1036 | AT9: 70.235 | AU9: 69.251 | AV9: 68.1376 | AW9: 66.8783 | AX9: 65.4536 | AY9: 63.8401 | AZ9: 62.0107 | BA9: 59.9329 | BB9: 57.569 | BC9: 54.8751 | BD9: 51.8009 | BE9: 48.2904 | BF9: 44.2837 | BG9: 39.7207 | BH9: 34.5487 | BI9: 28.7339 | BJ9: 22.2784 | BK9: 15.2394 | BL9: 7.7457 | BM9: 0
A10: 0 | B10: 6.8369 | C10: 13.4971 | D10: 19.8308 | E10: 25.7321 | F10: 31.1412 | G10: 36.0383 | H10: 40.4329 | I10: 44.3529 | J10: 47.8369 | K10: 50.9268 | L10: 53.6652 | M10: 56.0917 | N10: 58.2428 | O10: 60.1509 | P10: 61.8446 | Q10: 63.3486 | R10: 64.6844 | S10: 65.8704 | T10: 66.9225 | U10: 67.8541 | V10: 68.6768 | W10: 69.4007 | X10: 70.034 | Y10: 70.5839 | Z10: 71.0565 | AA10: 71.4567 | AB10: 71.7888 | AC10: 72.0561 | AD10: 72.2614 | AE10: 72.4066 | AF10: 72.4931 | AG10: 72.5219 | AH10: 72.4931 | AI10: 72.4066 | AJ10: 72.2614 | AK10: 72.0561 | AL10: 71.7888 | AM10: 71.4567 | AN10: 71.0565 | AO10: 70.5839 | AP10: 70.034 | AQ10: 69.4007 | AR10: 68.6768 | AS10: 67.8541 | AT10: 66.9225 | AU10: 65.8704 | AV10: 64.6844 | AW10: 63.3486 | AX10: 61.8446 | AY10: 60.1509 | AZ10: 58.2428 | BA10: 56.0917 | BB10: 53.6652 | BC10: 50.9268 | BD10: 47.8369 | BE10: 44.3529 | BF10: 40.4329 | BG10: 36.0383 | BH10: 31.1412 | BI10: 25.7321 | BJ10: 19.8308 | BK10: 13.4971 | BL10: 6.8369 | BM10: 0
A11: 0 | B11: 6.105 | C11: 12.0811 | D11: 17.8156 | E11: 23.2223 | F11: 28.2457 | G11: 32.8585 | H11: 37.0564 | I11: 40.8516 | J11: 44.2667 | K11: 47.3303 | L11: 50.0731 | M11: 52.5259 | N11: 54.7178 | O11: 56.6762 | P11: 58.4253 | Q11: 59.9872 | R11: 61.3811 | S11: 62.6238 | T11: 63.7303 | U11: 64.7134 | V11: 65.584 | W11: 66.3518 | X11: 67.025 | Y11: 67.6107 | Z11: 68.1147 | AA11: 68.5422 | AB11: 68.8973 | AC11: 69.1833 | AD11: 69.4031 | AE11: 69.5587 | AF11: 69.6514 | AG11: 69.6823 | AH11: 69.6514 | AI11: 69.5587 | AJ11: 69.4031 | AK11: 69.1833 | AL11: 68.8973 | AM11: 68.5422 | AN11: 68.1147 | AO11: 67.6107 | AP11: 67.025 | AQ11: 66.3518 | AR11: 65.584 | AS11: 64.7134 | AT11: 63.7303 | AU11: 62.6238 | AV11: 61.3811 | AW11: 59.9872 | AX11: 58.4253 | AY11: 56.6762 | AZ11: 54.7178 | BA11: 52.5259 | BB11: 50.0731 | BC11: 47.3303 | BD11: 44.2667 | BE11: 40.8516 | BF11: 37.0564 | BG11: 32.8585 | BH11: 28.2457 | BI11: 23.2223 | BJ11: 17.8156 | BK11: 12.0811 | BL11: 6.105 | BM11: 0
A12: 0 | B12: 5.5018 | C12: 10.9068 | D12: 16.1282 | E12: 21.096 | F12: 25.7608 | G12: 30.0936 | H12: 34.0827 | I12: 37.7303 | J12: 41.0482 | K12: 44.0546 | L12: 46.7711 | M12: 49.2208 | N12: 51.4266 | O12: 53.4106 | P12: 55.1933 | Q12: 56.7937 | R12: 58.2287 | S12: 59.5136 | T12: 60.6617 | U12: 61.685 | V12: 62.594 | W12: 63.3975 | X12: 64.1036 | Y12: 64.719 | Z12: 65.2496 | AA12: 65.7001 | AB12: 66.0747 | AC12: 66.3768 | AD12: 66.6091 | AE12: 66.7736 | AF12: 66.8717 | AG12: 66.9043 | AH12: 66.8717 | AI12: 66.7736 | AJ12: 66.6091 | AK12: 66.3768 | AL12: 66.0747 | AM12: 65.7001 | AN12: 65.2496 | AO12: 64.719 | AP12: 64.1036 | AQ12: 63.3975 | AR12: 62.594 | AS12: 61.685 | AT12: 60.6617 | AU12: 59.5136 | AV12: 58.2287 | AW12: 56.7937 | AX12: 55.1933 | AY12: 53.4106 | AZ12: 51.4266 | BA12: 49.2208 | BB12: 46.7711 | BC12: 44.0546 | BD12: 41.0482 | BE12: 37.7303 | BF12: 34.0827 | BG12: 30.0936 | BH12: 25.7608 | BI12: 21.096 | BJ12: 16.1282 | BK12: 10.9068 | BL12: 5.5018 | BM12: 0
... A65: 0 | B65: 0 | C65: 0 | D65: 0 | E65: 0 | F65: 0 | G65: 0 | H65: 0 | I65: 0 | J65: 0 | K65: 0 | L65: 0 | M65: 0 | N65: 0 | O65: 0 | P65: 0 | Q65: 0 | R65: 0 | S65: 0 | T65: 0 | U65: 0 | V65: 0 | W65: 0 | X65: 0 | Y65: 0 | Z65: 0 | AA65: 0 | AB65: 0 | AC65: 0 | AD65: 0 | AE65: 0 | AF65: 0 | AG65: 0 | AH65: 0 | AI65: 0 | AJ65: 0 | AK65: 0 | AL65: 0 | AM65: 0 | AN65: 0 | AO65: 0 | AP65: 0 | AQ65: 0 | AR65: 0 | AS65: 0 | AT65: 0 | AU65: 0 | AV65: 0 | AW65: 0 | AX65: 0 | AY65: 0 | AZ65: 0 | BA65: 0 | BB65: 0 | BC65: 0 | BD65: 0 | BE65: 0 | BF65: 0 | BG65: 0 | BH65: 0 | BI65: 0 | BJ65: 0 | BK65: 0 | BL65: 0 | BM65: 0

Sheet Middle_row
A1: j | B1: 3a uniform | C1: 3b edges | D1: 3c hot edge
A2: 0 | B2: =INDEX(Plate_3a!$A$1:$BM$65,33,A2+1) -> 75 | C2: =INDEX(Plate_3b!$A$1:$BM$65,33,A2+1) -> 20 | D2: =INDEX(Plate_3c!$A$1:$BM$65,33,A2+1) -> 0
A3: 1 | B3: =INDEX(Plate_3a!$A$1:$BM$65,33,A3+1) -> 75 | C3: =INDEX(Plate_3b!$A$1:$BM$65,33,A3+1) -> 21.1959 | D3: =INDEX(Plate_3c!$A$1:$BM$65,33,A3+1) -> 1.304
A4: 2 | B4: =INDEX(Plate_3a!$A$1:$BM$65,33,A4+1) -> 75 | C4: =INDEX(Plate_3b!$A$1:$BM$65,33,A4+1) -> 22.3871 | D4: =INDEX(Plate_3c!$A$1:$BM$65,33,A4+1) -> 2.6035
A5: 3 | B5: =INDEX(Plate_3a!$A$1:$BM$65,33,A5+1) -> 75 | C5: =INDEX(Plate_3b!$A$1:$BM$65,33,A5+1) -> 23.5691 | D5: =INDEX(Plate_3c!$A$1:$BM$65,33,A5+1) -> 3.8944
A6: 4 | B6: =INDEX(Plate_3a!$A$1:$BM$65,33,A6+1) -> 75 | C6: =INDEX(Plate_3b!$A$1:$BM$65,33,A6+1) -> 24.7373 | D6: =INDEX(Plate_3c!$A$1:$BM$65,33,A6+1) -> 5.1723
A7: 5 | B7: =INDEX(Plate_3a!$A$1:$BM$65,33,A7+1) -> 75 | C7: =INDEX(Plate_3b!$A$1:$BM$65,33,A7+1) -> 25.8874 | D7: =INDEX(Plate_3c!$A$1:$BM$65,33,A7+1) -> 6.4331
A8: 6 | B8: =INDEX(Plate_3a!$A$1:$BM$65,33,A8+1) -> 75 | C8: =INDEX(Plate_3b!$A$1:$BM$65,33,A8+1) -> 27.0152 | D8: =INDEX(Plate_3c!$A$1:$BM$65,33,A8+1) -> 7.6728
A9: 7 | B9: =INDEX(Plate_3a!$A$1:$BM$65,33,A9+1) -> 75 | C9: =INDEX(Plate_3b!$A$1:$BM$65,33,A9+1) -> 28.1166 | D9: =INDEX(Plate_3c!$A$1:$BM$65,33,A9+1) -> 8.8877
A10: 8 | B10: =INDEX(Plate_3a!$A$1:$BM$65,33,A10+1) -> 75 | C10: =INDEX(Plate_3b!$A$1:$BM$65,33,A10+1) -> 29.1878 | D10: =INDEX(Plate_3c!$A$1:$BM$65,33,A10+1) -> 10.0743
A11: 9 | B11: =INDEX(Plate_3a!$A$1:$BM$65,33,A11+1) -> 75 | C11: =INDEX(Plate_3b!$A$1:$BM$65,33,A11+1) -> 30.2253 | D11: =INDEX(Plate_3c!$A$1:$BM$65,33,A11+1) -> 11.2292
A12: 10 | B12: =INDEX(Plate_3a!$A$1:$BM$65,33,A12+1) -> 75 | C12: =INDEX(Plate_3b!$A$1:$BM$65,33,A12+1) -> 31.2257 | D12: =INDEX(Plate_3c!$A$1:$BM$65,33,A12+1) -> 12.3495
A13: 11 | B13: =INDEX(Plate_3a!$A$1:$BM$65,33,A13+1) -> 75 | C13: =INDEX(Plate_3b!$A$1:$BM$65,33,A13+1) -> 32.186 | D13: =INDEX(Plate_3c!$A$1:$BM$65,33,A13+1) -> 13.4323
... A66: 64 | B66: =INDEX(Plate_3a!$A$1:$BM$65,33,A66+1) -> 75 | C66: =INDEX(Plate_3b!$A$1:$BM$65,33,A66+1) -> 0 | D66: =INDEX(Plate_3c!$A$1:$BM$65,33,A66+1) -> 0
