Workbook

Sheet Sweep 1
A1: Sweep 1 on a 6 × 6 grid
A2: Jacobi update: every new value is the average of its four neighbours taken from the OLD grid only. Boundary cells never change.
B4: T_old: grid before sweep 1 | J4: T_new: grid after sweep 1
B5: j=0 | C5: j=1 | D5: j=2 | E5: j=3 | F5: j=4 | G5: j=5 | J5: j=0 | K5: j=1 | L5: j=2 | M5: j=3 | N5: j=4 | O5: j=5
A6: i=0 | B6: =AVERAGE(Inputs!$C$3,Inputs!$C$5) -> 50 | C6: =Inputs!$C$3 -> 100 | D6: =Inputs!$C$3 -> 100 | E6: =Inputs!$C$3 -> 100 | F6: =Inputs!$C$3 -> 100 | G6: =AVERAGE(Inputs!$C$3,Inputs!$C$6) -> 50 | I6: i=0 | J6: =B6 -> 50 | K6: =C6 -> 100 | L6: =D6 -> 100 | M6: =E6 -> 100 | N6: =F6 -> 100 | O6: =G6 -> 50
A7: i=1 | B7: =Inputs!$C$5 -> 0 | C7: =Inputs!$C$7 -> 0 | D7: =Inputs!$C$7 -> 0 | E7: =Inputs!$C$7 -> 0 | F7: =Inputs!$C$7 -> 0 | G7: =Inputs!$C$6 -> 0 | I7: i=1 | J7: =B7 -> 0 | K7: =H25 -> 25 | L7: =H26 -> 25 | M7: =H27 -> 25 | N7: =H28 -> 25 | O7: =G7 -> 0
A8: i=2 | B8: =Inputs!$C$5 -> 0 | C8: =Inputs!$C$7 -> 0 | D8: =Inputs!$C$7 -> 0 | E8: =Inputs!$C$7 -> 0 | F8: =Inputs!$C$7 -> 0 | G8: =Inputs!$C$6 -> 0 | I8: i=2 | J8: =B8 -> 0 | K8: =H29 -> 0 | L8: =H30 -> 0 | M8: =H31 -> 0 | N8: =H32 -> 0 | O8: =G8 -> 0
A9: i=3 | B9: =Inputs!$C$5 -> 0 | C9: =Inputs!$C$7 -> 0 | D9: =Inputs!$C$7 -> 0 | E9: =Inputs!$C$7 -> 0 | F9: =Inputs!$C$7 -> 0 | G9: =Inputs!$C$6 -> 0 | I9: i=3 | J9: =B9 -> 0 | K9: =H33 -> 0 | L9: =H34 -> 0 | M9: =H35 -> 0 | N9: =H36 -> 0 | O9: =G9 -> 0
A10: i=4 | B10: =Inputs!$C$5 -> 0 | C10: =Inputs!$C$7 -> 0 | D10: =Inputs!$C$7 -> 0 | E10: =Inputs!$C$7 -> 0 | F10: =Inputs!$C$7 -> 0 | G10: =Inputs!$C$6 -> 0 | I10: i=4 | J10: =B10 -> 0 | K10: =H37 -> 25 | L10: =H38 -> 25 | M10: =H39 -> 25 | N10: =H40 -> 25 | O10: =G10 -> 0
A11: i=5 | B11: =AVERAGE(Inputs!$C$4,Inputs!$C$5) -> 50 | C11: =Inputs!$C$4 -> 100 | D11: =Inputs!$C$4 -> 100 | E11: =Inputs!$C$4 -> 100 | F11: =Inputs!$C$4 -> 100 | G11: =AVERAGE(Inputs!$C$4,Inputs!$C$6) -> 50 | I11: i=5 | J11: =B11 -> 50 | K11: =C11 -> 100 | L11: =D11 -> 100 | M11: =E11 -> 100 | N11: =F11 -> 100 | O11: =G11 -> 50
B12: Corner cells are never used by the stencil. They are shown as the average of their two edges.
B13: |T_new − T_old|: change in each cell
B14: j=0 | C14: j=1 | D14: j=2 | E14: j=3 | F14: j=4 | G14: j=5 | I14: Convergence check
A15: i=0 | B15: =ABS(J6-B6) -> 0 | C15: =ABS(K6-C6) -> 0 | D15: =ABS(L6-D6) -> 0 | E15: =ABS(M6-E6) -> 0 | F15: =ABS(N6-F6) -> 0 | G15: =ABS(O6-G6) -> 0 | I15: Max change in this sweep | J15: =MAX(C16:F19) -> 25
A16: i=1 | B16: =ABS(J7-B7) -> 0 | C16: =ABS(K7-C7) -> 25 | D16: =ABS(L7-D7) -> 25 | E16: =ABS(M7-E7) -> 25 | F16: =ABS(N7-F7) -> 25 | G16: =ABS(O7-G7) -> 0 | I16: Tolerance ε | J16: =Inputs!$C$8 -> 0.1
A17: i=2 | B17: =ABS(J8-B8) -> 0 | C17: =ABS(K8-C8) -> 0 | D17: =ABS(L8-D8) -> 0 | E17: =ABS(M8-E8) -> 0 | F17: =ABS(N8-F8) -> 0 | G17: =ABS(O8-G8) -> 0 | I17: Converged? | J17: =IF(J15<J16,"YES: stop","NO: do another sweep") -> NO: do another sweep
A18: i=3 | B18: =ABS(J9-B9) -> 0 | C18: =ABS(K9-C9) -> 0 | D18: =ABS(L9-D9) -> 0 | E18: =ABS(M9-E9) -> 0 | F18: =ABS(N9-F9) -> 0 | G18: =ABS(O9-G9) -> 0
A19: i=4 | B19: =ABS(J10-B10) -> 0 | C19: =ABS(K10-C10) -> 25 | D19: =ABS(L10-D10) -> 25 | E19: =ABS(M10-E10) -> 25 | F19: =ABS(N10-F10) -> 25 | G19: =ABS(O10-G10) -> 0 | I19: Max change uses the 4 × 4 interior only.
A20: i=5 | B20: =ABS(J11-B11) -> 0 | C20: =ABS(K11-C11) -> 0 | D20: =ABS(L11-D11) -> 0 | E20: =ABS(M11-E11) -> 0 | F20: =ABS(N11-F11) -> 0 | G20: =ABS(O11-G11) -> 0
A22: Cell-by-cell calculation (interior cells, row by row)
A23: Formula in every row: T_new(i,j) = [ above + below + left + right ] ÷ 4. The cell's own old value is only used to measure the change.
B24: Cell (i,j) | C24: Above T_old(i−1,j) | D24: Below T_old(i+1,j) | E24: Left T_old(i,j−1) | F24: Right T_old(i,j+1) | G24: Sum of four | H24: T_new = Sum ÷ 4 | I24: Old value T_old(i,j) | J24: |Change|
B25: (1,1) | C25: =C6 -> 100 | D25: =C8 -> 0 | E25: =B7 -> 0 | F25: =D7 -> 0 | G25: =SUM(C25:F25) -> 100 | H25: =G25/4 -> 25 | I25: =C7 -> 0 | J25: =ABS(H25-I25) -> 25
B26: (1,2) | C26: =D6 -> 100 | D26: =D8 -> 0 | E26: =C7 -> 0 | F26: =E7 -> 0 | G26: =SUM(C26:F26) -> 100 | H26: =G26/4 -> 25 | I26: =D7 -> 0 | J26: =ABS(H26-I26) -> 25
B27: (1,3) | C27: =E6 -> 100 | D27: =E8 -> 0 | E27: =D7 -> 0 | F27: =F7 -> 0 | G27: =SUM(C27:F27) -> 100 | H27: =G27/4 -> 25 | I27: =E7 -> 0 | J27: =ABS(H27-I27) -> 25
B28: (1,4) | C28: =F6 -> 100 | D28: =F8 -> 0 | E28: =E7 -> 0 | F28: =G7 -> 0 | G28: =SUM(C28:F28) -> 100 | H28: =G28/4 -> 25 | I28: =F7 -> 0 | J28: =ABS(H28-I28) -> 25
B29: (2,1) | C29: =C7 -> 0 | D29: =C9 -> 0 | E29: =B8 -> 0 | F29: =D8 -> 0 | G29: =SUM(C29:F29) -> 0 | H29: =G29/4 -> 0 | I29: =C8 -> 0 | J29: =ABS(H29-I29) -> 0
B30: (2,2) | C30: =D7 -> 0 | D30: =D9 -> 0 | E30: =C8 -> 0 | F30: =E8 -> 0 | G30: =SUM(C30:F30) -> 0 | H30: =G30/4 -> 0 | I30: =D8 -> 0 | J30: =ABS(H30-I30) -> 0
B31: (2,3) | C31: =E7 -> 0 | D31: =E9 -> 0 | E31: =D8 -> 0 | F31: =F8 -> 0 | G31: =SUM(C31:F31) -> 0 | H31: =G31/4 -> 0 | I31: =E8 -> 0 | J31: =ABS(H31-I31) -> 0
B32: (2,4) | C32: =F7 -> 0 | D32: =F9 -> 0 | E32: =E8 -> 0 | F32: =G8 -> 0 | G32: =SUM(C32:F32) -> 0 | H32: =G32/4 -> 0 | I32: =F8 -> 0 | J32: =ABS(H32-I32) -> 0
B33: (3,1) | C33: =C8 -> 0 | D33: =C10 -> 0 | E33: =B9 -> 0 | F33: =D9 -> 0 | G33: =SUM(C33:F33) -> 0 | H33: =G33/4 -> 0 | I33: =C9 -> 0 | J33: =ABS(H33-I33) -> 0
B34: (3,2) | C34: =D8 -> 0 | D34: =D10 -> 0 | E34: =C9 -> 0 | F34: =E9 -> 0 | G34: =SUM(C34:F34) -> 0 | H34: =G34/4 -> 0 | I34: =D9 -> 0 | J34: =ABS(H34-I34) -> 0
B35: (3,3) | C35: =E8 -> 0 | D35: =E10 -> 0 | E35: =D9 -> 0 | F35: =F9 -> 0 | G35: =SUM(C35:F35) -> 0 | H35: =G35/4 -> 0 | I35: =E9 -> 0 | J35: =ABS(H35-I35) -> 0
B36: (3,4) | C36: =F8 -> 0 | D36: =F10 -> 0 | E36: =E9 -> 0 | F36: =G9 -> 0 | G36: =SUM(C36:F36) -> 0 | H36: =G36/4 -> 0 | I36: =F9 -> 0 | J36: =ABS(H36-I36) -> 0
B37: (4,1) | C37: =C9 -> 0 | D37: =C11 -> 100 | E37: =B10 -> 0 | F37: =D10 -> 0 | G37: =SUM(C37:F37) -> 100 | H37: =G37/4 -> 25 | I37: =C10 -> 0 | J37: =ABS(H37-I37) -> 25
B38: (4,2) | C38: =D9 -> 0 | D38: =D11 -> 100 | E38: =C10 -> 0 | F38: =E10 -> 0 | G38: =SUM(C38:F38) -> 100 | H38: =G38/4 -> 25 | I38: =D10 -> 0 | J38: =ABS(H38-I38) -> 25
B39: (4,3) | C39: =E9 -> 0 | D39: =E11 -> 100 | E39: =D10 -> 0 | F39: =F10 -> 0 | G39: =SUM(C39:F39) -> 100 | H39: =G39/4 -> 25 | I39: =E10 -> 0 | J39: =ABS(H39-I39) -> 25
B40: (4,4) | C40: =F9 -> 0 | D40: =F11 -> 100 | E40: =E10 -> 0 | F40: =G10 -> 0 | G40: =SUM(C40:F40) -> 100 | H40: =G40/4 -> 25 | I40: =F10 -> 0 | J40: =ABS(H40-I40) -> 25
A42: With the default inputs, reading the first row: cell (1,1) has 100 above it and 25 to its right (from sweep 1), so (100 + 0 + 0 + 25) ÷ 4 = 31.25. Row 2 now warms up too, because its upper neighbours became 25.
A43: Each new sweep repeats the same steps, using T_new as the next T_old, until the max change drops below ε.

Sheet Sweep 2
A1: Sweep 2 on a 6 × 6 grid
A2: Jacobi update: every new value is the average of its four neighbours taken from the OLD grid only. Boundary cells never change.
A3: T_old on this sheet is linked to T_new on 'Sweep 1', so this sweep starts exactly where the last one stopped.
B4: T_old: grid before sweep 2 | J4: T_new: grid after sweep 2
B5: j=0 | C5: j=1 | D5: j=2 | E5: j=3 | F5: j=4 | G5: j=5 | J5: j=0 | K5: j=1 | L5: j=2 | M5: j=3 | N5: j=4 | O5: j=5
A6: i=0 | B6: ='Sweep 1'!J6 -> 50 | C6: ='Sweep 1'!K6 -> 100 | D6: ='Sweep 1'!L6 -> 100 | E6: ='Sweep 1'!M6 -> 100 | F6: ='Sweep 1'!N6 -> 100 | G6: ='Sweep 1'!O6 -> 50 | I6: i=0 | J6: =B6 -> 50 | K6: =C6 -> 100 | L6: =D6 -> 100 | M6: =E6 -> 100 | N6: =F6 -> 100 | O6: =G6 -> 50
A7: i=1 | B7: ='Sweep 1'!J7 -> 0 | C7: ='Sweep 1'!K7 -> 25 | D7: ='Sweep 1'!L7 -> 25 | E7: ='Sweep 1'!M7 -> 25 | F7: ='Sweep 1'!N7 -> 25 | G7: ='Sweep 1'!O7 -> 0 | I7: i=1 | J7: =B7 -> 0 | K7: =H25 -> 31.25 | L7: =H26 -> 37.5 | M7: =H27 -> 37.5 | N7: =H28 -> 31.25 | O7: =G7 -> 0
A8: i=2 | B8: ='Sweep 1'!J8 -> 0 | C8: ='Sweep 1'!K8 -> 0 | D8: ='Sweep 1'!L8 -> 0 | E8: ='Sweep 1'!M8 -> 0 | F8: ='Sweep 1'!N8 -> 0 | G8: ='Sweep 1'!O8 -> 0 | I8: i=2 | J8: =B8 -> 0 | K8: =H29 -> 6.25 | L8: =H30 -> 6.25 | M8: =H31 -> 6.25 | N8: =H32 -> 6.25 | O8: =G8 -> 0
A9: i=3 | B9: ='Sweep 1'!J9 -> 0 | C9: ='Sweep 1'!K9 -> 0 | D9: ='Sweep 1'!L9 -> 0 | E9: ='Sweep 1'!M9 -> 0 | F9: ='Sweep 1'!N9 -> 0 | G9: ='Sweep 1'!O9 -> 0 | I9: i=3 | J9: =B9 -> 0 | K9: =H33 -> 6.25 | L9: =H34 -> 6.25 | M9: =H35 -> 6.25 | N9: =H36 -> 6.25 | O9: =G9 -> 0
A10: i=4 | B10: ='Sweep 1'!J10 -> 0 | C10: ='Sweep 1'!K10 -> 25 | D10: ='Sweep 1'!L10 -> 25 | E10: ='Sweep 1'!M10 -> 25 | F10: ='Sweep 1'!N10 -> 25 | G10: ='Sweep 1'!O10 -> 0 | I10: i=4 | J10: =B10 -> 0 | K10: =H37 -> 31.25 | L10: =H38 -> 37.5 | M10: =H39 -> 37.5 | N10: =H40 -> 31.25 | O10: =G10 -> 0
A11: i=5 | B11: ='Sweep 1'!J11 -> 50 | C11: ='Sweep 1'!K11 -> 100 | D11: ='Sweep 1'!L11 -> 100 | E11: ='Sweep 1'!M11 -> 100 | F11: ='Sweep 1'!N11 -> 100 | G11: ='Sweep 1'!O11 -> 50 | I11: i=5 | J11: =B11 -> 50 | K11: =C11 -> 100 | L11: =D11 -> 100 | M11: =E11 -> 100 | N11: =F11 -> 100 | O11: =G11 -> 50
B12: Corner cells are never used by the stencil. They are shown as the average of their two edges.
B13: |T_new − T_old|: change in each cell
B14: j=0 | C14: j=1 | D14: j=2 | E14: j=3 | F14: j=4 | G14: j=5 | I14: Convergence check
A15: i=0 | B15: =ABS(J6-B6) -> 0 | C15: =ABS(K6-C6) -> 0 | D15: =ABS(L6-D6) -> 0 | E15: =ABS(M6-E6) -> 0 | F15: =ABS(N6-F6) -> 0 | G15: =ABS(O6-G6) -> 0 | I15: Max change in this sweep | J15: =MAX(C16:F19) -> 12.5
A16: i=1 | B16: =ABS(J7-B7) -> 0 | C16: =ABS(K7-C7) -> 6.25 | D16: =ABS(L7-D7) -> 12.5 | E16: =ABS(M7-E7) -> 12.5 | F16: =ABS(N7-F7) -> 6.25 | G16: =ABS(O7-G7) -> 0 | I16: Tolerance ε | J16: =Inputs!$C$8 -> 0.1
A17: i=2 | B17: =ABS(J8-B8) -> 0 | C17: =ABS(K8-C8) -> 6.25 | D17: =ABS(L8-D8) -> 6.25 | E17: =ABS(M8-E8) -> 6.25 | F17: =ABS(N8-F8) -> 6.25 | G17: =ABS(O8-G8) -> 0 | I17: Converged? | J17: =IF(J15<J16,"YES: stop","NO: do another sweep") -> NO: do another sweep
A18: i=3 | B18: =ABS(J9-B9) -> 0 | C18: =ABS(K9-C9) -> 6.25 | D18: =ABS(L9-D9) -> 6.25 | E18: =ABS(M9-E9) -> 6.25 | F18: =ABS(N9-F9) -> 6.25 | G18: =ABS(O9-G9) -> 0
A19: i=4 | B19: =ABS(J10-B10) -> 0 | C19: =ABS(K10-C10) -> 6.25 | D19: =ABS(L10-D10) -> 12.5 | E19: =ABS(M10-E10) -> 12.5 | F19: =ABS(N10-F10) -> 6.25 | G19: =ABS(O10-G10) -> 0 | I19: Max change uses the 4 × 4 interior only.
A20: i=5 | B20: =ABS(J11-B11) -> 0 | C20: =ABS(K11-C11) -> 0 | D20: =ABS(L11-D11) -> 0 | E20: =ABS(M11-E11) -> 0 | F20: =ABS(N11-F11) -> 0 | G20: =ABS(O11-G11) -> 0
A22: Cell-by-cell calculation (interior cells, row by row)
A23: Formula in every row: T_new(i,j) = [ above + below + left + right ] ÷ 4. The cell's own old value is only used to measure the change.
B24: Cell (i,j) | C24: Above T_old(i−1,j) | D24: Below T_old(i+1,j) | E24: Left T_old(i,j−1) | F24: Right T_old(i,j+1) | G24: Sum of four | H24: T_new = Sum ÷ 4 | I24: Old value T_old(i,j) | J24: |Change|
B25: (1,1) | C25: =C6 -> 100 | D25: =C8 -> 0 | E25: =B7 -> 0 | F25: =D7 -> 25 | G25: =SUM(C25:F25) -> 125 | H25: =G25/4 -> 31.25 | I25: =C7 -> 25 | J25: =ABS(H25-I25) -> 6.25
B26: (1,2) | C26: =D6 -> 100 | D26: =D8 -> 0 | E26: =C7 -> 25 | F26: =E7 -> 25 | G26: =SUM(C26:F26) -> 150 | H26: =G26/4 -> 37.5 | I26: =D7 -> 25 | J26: =ABS(H26-I26) -> 12.5
B27: (1,3) | C27: =E6 -> 100 | D27: =E8 -> 0 | E27: =D7 -> 25 | F27: =F7 -> 25 | G27: =SUM(C27:F27) -> 150 | H27: =G27/4 -> 37.5 | I27: =E7 -> 25 | J27: =ABS(H27-I27) -> 12.5
B28: (1,4) | C28: =F6 -> 100 | D28: =F8 -> 0 | E28: =E7 -> 25 | F28: =G7 -> 0 | G28: =SUM(C28:F28) -> 125 | H28: =G28/4 -> 31.25 | I28: =F7 -> 25 | J28: =ABS(H28-I28) -> 6.25
B29: (2,1) | C29: =C7 -> 25 | D29: =C9 -> 0 | E29: =B8 -> 0 | F29: =D8 -> 0 | G29: =SUM(C29:F29) -> 25 | H29: =G29/4 -> 6.25 | I29: =C8 -> 0 | J29: =ABS(H29-I29) -> 6.25
B30: (2,2) | C30: =D7 -> 25 | D30: =D9 -> 0 | E30: =C8 -> 0 | F30: =E8 -> 0 | G30: =SUM(C30:F30) -> 25 | H30: =G30/4 -> 6.25 | I30: =D8 -> 0 | J30: =ABS(H30-I30) -> 6.25
B31: (2,3) | C31: =E7 -> 25 | D31: =E9 -> 0 | E31: =D8 -> 0 | F31: =F8 -> 0 | G31: =SUM(C31:F31) -> 25 | H31: =G31/4 -> 6.25 | I31: =E8 -> 0 | J31: =ABS(H31-I31) -> 6.25
B32: (2,4) | C32: =F7 -> 25 | D32: =F9 -> 0 | E32: =E8 -> 0 | F32: =G8 -> 0 | G32: =SUM(C32:F32) -> 25 | H32: =G32/4 -> 6.25 | I32: =F8 -> 0 | J32: =ABS(H32-I32) -> 6.25
B33: (3,1) | C33: =C8 -> 0 | D33: =C10 -> 25 | E33: =B9 -> 0 | F33: =D9 -> 0 | G33: =SUM(C33:F33) -> 25 | H33: =G33/4 -> 6.25 | I33: =C9 -> 0 | J33: =ABS(H33-I33) -> 6.25
B34: (3,2) | C34: =D8 -> 0 | D34: =D10 -> 25 | E34: =C9 -> 0 | F34: =E9 -> 0 | G34: =SUM(C34:F34) -> 25 | H34: =G34/4 -> 6.25 | I34: =D9 -> 0 | J34: =ABS(H34-I34) -> 6.25
B35: (3,3) | C35: =E8 -> 0 | D35: =E10 -> 25 | E35: =D9 -> 0 | F35: =F9 -> 0 | G35: =SUM(C35:F35) -> 25 | H35: =G35/4 -> 6.25 | I35: =E9 -> 0 | J35: =ABS(H35-I35) -> 6.25
B36: (3,4) | C36: =F8 -> 0 | D36: =F10 -> 25 | E36: =E9 -> 0 | F36: =G9 -> 0 | G36: =SUM(C36:F36) -> 25 | H36: =G36/4 -> 6.25 | I36: =F9 -> 0 | J36: =ABS(H36-I36) -> 6.25
B37: (4,1) | C37: =C9 -> 0 | D37: =C11 -> 100 | E37: =B10 -> 0 | F37: =D10 -> 25 | G37: =SUM(C37:F37) -> 125 | H37: =G37/4 -> 31.25 | I37: =C10 -> 25 | J37: =ABS(H37-I37) -> 6.25
B38: (4,2) | C38: =D9 -> 0 | D38: =D11 -> 100 | E38: =C10 -> 25 | F38: =E10 -> 25 | G38: =SUM(C38:F38) -> 150 | H38: =G38/4 -> 37.5 | I38: =D10 -> 25 | J38: =ABS(H38-I38) -> 12.5
B39: (4,3) | C39: =E9 -> 0 | D39: =E11 -> 100 | E39: =D10 -> 25 | F39: =F10 -> 25 | G39: =SUM(C39:F39) -> 150 | H39: =G39/4 -> 37.5 | I39: =E10 -> 25 | J39: =ABS(H39-I39) -> 12.5
B40: (4,4) | C40: =F9 -> 0 | D40: =F11 -> 100 | E40: =E10 -> 25 | F40: =G10 -> 0 | G40: =SUM(C40:F40) -> 125 | H40: =G40/4 -> 31.25 | I40: =F10 -> 25 | J40: =ABS(H40-I40) -> 6.25
A42: With the default inputs, reading the first row: cell (1,1) has 100 above it and 25 to its right (from sweep 1), so (100 + 0 + 0 + 25) ÷ 4 = 31.25. Row 2 now warms up too, because its upper neighbours became 25.
...

Sheet Inputs
B1: Inputs
B2: Blue cells on a yellow fill are the only cells you edit. The other sheets recalculate.
B3: Top edge temperature (°) | C3: 100 | D3: Row 0, held fixed. Same as the web page screenshot.
B4: Bottom edge temperature (°) | C4: 100 | D4: Row 5, held fixed.
B5: Left edge temperature (°) | C5: 0 | D5: Column 0, held fixed.
B6: Right edge temperature (°) | C6: 0 | D6: Column 5, held fixed.
B7: Starting interior temperature (°) | C7: 0 | D7: Every interior cell starts at this value (the page starts at 0°).
B8: Tolerance ε | C8: 0.1 | D8: Stop when the largest change in one sweep is below this.
B9: Grid size N | C9: 6 | D9: Fixed at 6 × 6 in this workbook: 4 × 4 interior cells plus a one-cell border.
B11: Example row
B12: Top 100, Bottom 100, Left 0, Right 0, Interior 0, ε 0.1 is the setting that converged in 24 sweeps on the web page.

Sheet Theory
B1: Theory behind the calculation
B3: 1. The physical problem
B4: A thin plate is held at fixed temperatures on its four edges. Heat flows from hot to cold until the temperatures stop changing. The final state is the steady state of the heat equation, written T_t = α(T_xx + T_yy). At steady state T_t = 0, which gives Laplace's equation: T_xx + T_yy = 0.
B6: 2. Finite differences
B7: Cut the plate into a grid with spacing h. The second derivative in each direction is approximated by T_xx ≈ [T(i,j+1) − 2T(i,j) + T(i,j−1)] ÷ h² and T_yy ≈ [T(i+1,j) − 2T(i,j) + T(i−1,j)] ÷ h². Adding them and setting the sum to zero gives: T(i−1,j) + T(i+1,j) + T(i,j−1) + T(i,j+1) − 4T(i,j) = 0. This is the five-point stencil: it uses the centre cell and its four neighbours.
B9: 3. The averaging rule
B10: Solving the stencil equation for T(i,j) gives T(i,j) = [T(i−1,j) + T(i+1,j) + T(i,j−1) + T(i,j+1)] ÷ 4. At steady state every interior cell equals the average of its four neighbours. The same rule also comes from stepping the heat equation forward in time with the explicit method: T_new = T + r × (sum of four − 4T). Choosing r = α·Δt ÷ h² = 1/4 cancels the T terms and leaves the plain average.
B12: 4. Jacobi iteration
B13: The averaging equations for all interior cells form a linear system, and the Jacobi method solves it by repeating the averaging. Each sweep computes the whole new grid from the old grid only. In code this is double buffering: read from one array, write to another, then swap. Gauss–Seidel is a faster variant that reuses new values immediately, but it is not what this workbook uses.
B15: 5. Boundary conditions
B16: The edges use fixed-temperature (Dirichlet) conditions. Boundary cells are never recalculated. Interior cells next to an edge read the edge value as their neighbour, which is how heat enters or leaves the plate. Interior cells touching two edges simply have two fixed neighbours.
B18: 6. Convergence detection
... B24: Estimate of sweeps needed (rough guide, uses the inputs on the Inputs sheet)
B25: Interior cells per side, n = N − 2 | C25: =Inputs!$C$9-2 -> 4
B26: Error shrink factor per sweep, ρ = cos(π ÷ (n + 1)) | C26: =COS(PI()/(C25+1)) -> 0.80901699
B27: Largest change in sweep 1 | C27: ='Sweep 1'!J15 -> 25
B28: Tolerance ε | C28: =Inputs!$C$8 -> 0.1
B29: Estimated sweeps to converge | C29: =IF(C27<=C28,1,ROUNDUP(LN(C28/C27)/LN(C26),0)) -> 27
B31: The web page converged in 24 sweeps for the default inputs. The estimate lands close to that. It is a guide, not an exact count.
